Workbook
Name BANCODECONDESADORES: FAMILIAS!$S$2:$S$11
Name COMPONENTES: LISTA!$Z$1:$AV$1
Name CONDUCTOR: LISTA!$AS$2:$AS$4
Name CONECTOR: AISLADORESSOPORTE[CONECTOR]
Name ESTADO: [2]LISTA!#REF!
Name ESTATUS: LISTA!$AX$2:$AX$4
Name FAMILIAS: FAMILIAS!$A$1:$X$1
Name HERRAJE: LISTA!$AU$2:$AU$3
Name REGION: LISTA!$C$2:$C$9
Name TENSIONCIRCUITO: LISTA!$T$2:$T$15
Name TENSIONSUBESTACION: LISTA!$R$2:$R$14
Name TIPORESTRICCIONES: LISTA!$V$2:$V$11
Name TRANSFORMADORESDEPOTENCIA: EQUIPOSDESUBESTACIONES2[TRANSFORMADORESDEPOTENCIA]
Name UNIDAD: LISTA!$P$2:$P$13

Sheet EQUIPOS INDISPONIBLES SE
A1: IDENTIFICADOR EQUIPO O COMPONENTE A NORMALIZAR | B1: REGION | C1: ESTADO | D1: NOMBRE SUBESTACIÓN | E1: NIVEL TENSION ENTRADA | F1: COMPONENTE DE LA SUBESTACION | G1: TIPO DE EQUIPO O ELEMENTO A NORMALIZAR EN LA SUBESTACION | H1: ESPECIFICACIONES TECNICAS DEL EQUIPO O ELEMENTOS REQUERIDO (NÚMERO DE NORMA QUE REGULA AL EQUIPO O COMPONENTE) | I1: ACCIÓN OPERATIVA (BREVE DESCRIPCION DE LOS TRABAJOS A REALIZAR) | J1: NOMENCLATURA DEL EQUIPO (CÓDIGO QUE IDENTIFICA AL COMPONENTE EN LA SE) | K1: ESTATUS | L1: N° DE PRIORIDAD | M1: UNIDAD | N1: CANTIDAD DE EQUIPO A O COMPONENTE A NORMALIZAR | O1: FECHA PROGRAMADA DE INTERVENCION
A2: 1 | B2: ORIENTAL | C2: SUCRE | D2: ARAYA | E2: 34.5 | F2: TRANSFORMADORDEPOTENCIA | G2: ACEITE DIELECTRICO | H2: ACEITE DIELECTRICO CON UN NIVEL DE AISLAMIENTO SUPERIOR A LOS 42 KV | I2: REPOSICIÓN DE ACEITE DIELÉCTRICO A TRANSFORMADOR DE POTENCIA DE LA SUBESTACIÓN | J2: 0 | K2: RESUELTO | L2: ALTA | M2: TB | N2: 15 | O2: 45694
A3: 2 | B3: ORIENTAL | C3: SUCRE | D3: ARAYA | E3: 34.5 | F3: INTERRUPTOR | G3: INTERRUPTOR 34,5 kV | H3: DISYUNTOR DIGITAL DE 34.5 KV, DE 400 AMP, MARCA TABLECEL | I3: REEMPLAZO DE DISYUNTOR 34,5 KV | J3: B110 | K3: PENDIENTE | L3: ALTA | M3: PZA | N3: 1 | O3: DEL 02-03-2026 AL 31-12-2026
A4: 3 | B4: ORIENTAL | C4: SUCRE | D4: ARAYA | E4: 34.5 | F4: RECONECTADOR | G4: RECONECTADOR 13,8 KV | H4: RECONECTADOR DIGITAL DE 13.8 KV, DE 250 AMP, MARCA NOJA O ROCKWILL | I4: REEMPLAZO DE RECONECTADOR 13,8 KV EN LA SALIDA DEL CIRCUITO 13,8 KV ENSAL II | J4: D205 | K4: PENDIENTE | L4: ALTA | M4: PZA | N4: 1 | O4: DEL 02-03-2026 AL 31-12-2026
A5: 4 | B5: ORIENTAL | C5: SUCRE | D5: CASANAY | E5: 34.5 | F5: RECONECTADOR | G5: RECONECTADOR 13,8 KV | H5: RECONECTADOR DIGITAL DE 13.8 KV, DE 250 AMP, MARCA NOJA O ROCKWILL | I5: REEMPLAZO DE RECONECTADOR 13,8 KV EN LA SALIDA DEL CIRCUITO 13,8 KV LA MARAVILLA | J5: D305 | K5: RESUELTO | L5: ALTA | M5: PZA | N5: 1 | O5: DEL 02-03-2026 AL 31-12-2026
A6: 5 | B6: ORIENTAL | C6: SUCRE | D6: CATUARO | E6: 34.5 | F6: RECONECTADOR | G6: RECONECTADOR 13,8 KV | H6: RECONECTADOR DIGITAL DE 13.8 KV, DE 100 AMP, MARCA NOJA O ROCKWILL | I6: REEMPLAZO DE RECONECTADOR 13,8 KV EN LA SALIDA DEL CIRCUITO 13,8 KV LA SABANA | J6: D205 | K6: PENDIENTE | L6: ALTA | M6: PZA | N6: 1 | O6: DEL 02-03-2026 AL 31-12-2026
A7: 6 | B7: ORIENTAL | C7: SUCRE | D7: CATUARO | E7: 34.5 | F7: RECONECTADOR | G7: RECONECTADOR 13,8 KV | H7: RECONECTADOR DIGITAL DE 13.8 KV, DE 100 AMP, MARCA NOJA O ROCKWILL | I7: REEMPLAZO DE RECONECTADOR 13,8 KV EN LA SALIDA DEL CIRCUITO 13,8 KV CATUARO | J7: D105 | K7: PENDIENTE | L7: ALTA | M7: PZA | N7: 1 | O7: DEL 02-03-2026 AL 31-12-2026
A8: 7 | B8: ORIENTAL | C8: SUCRE | D8: CUMANACOA | E8: 34.5 | F8: RECONECTADOR | G8: RECONECTADOR 13,8 KV | H8: RECONECTADOR DIGITAL DE 13.8 KV, DE 200 AMP, MARCA NOJA O ROCKWILL | I8: REEMPLAZO DE RECONECTADOR 13,8 KV EN LA SALIDA DEL CIRCUITO 13,8 KV SAN LORENZO | J8: D405 | K8: RESUELTO | L8: ALTA | M8: PZA | N8: 1 | O8: 45736
A9: 8 | B9: ORIENTAL | C9: SUCRE | D9: CUMANACOA | E9: 34.5 | F9: RECONECTADOR | G9: RECONECTADOR 13,8 KV | H9: RECONECTADOR DIGITAL DE 13.8 KV, DE 200 AMP, MARCA NOJA O ROCKWILL | I9: REEMPLAZO DE RECONECTADOR 13,8 KV EN LA SALIDA DEL CIRCUITO 13,8 KV CENTRAL AZUCARERO | J9: D305 | K9: PENDIENTE | L9: ALTA | M9: PZA | N9: 1 | O9: DEL 02-03-2026 AL 31-12-2026
A10: 9 | B10: ORIENTAL | C10: SUCRE | D10: EL LOCO | E10: 34.5 | F10: RECONECTADOR | G10: RECONECTADOR 13,8 KV | H10: RECONECTADOR DIGITAL DE 13.8 KV, DE 100 AMP, MARCA NOJA O ROCKWILL | I10: REEMPLAZO DE RECONECTADOR 13,8 KV EN LA SALIDA DEL CIRCUITO 13,8 KV SOTILLO | J10: D105 | K10: PENDIENTE | L10: ALTA | M10: PZA | N10: 1 | O10: DEL 02-03-2026 AL 31-12-2026
A11: 10 | B11: ORIENTAL | C11: SUCRE | D11: EL LOCO | E11: 34.5 | F11: RECONECTADOR | G11: RECONECTADOR 13,8 KV | H11: RECONECTADOR DIGITAL DE 13.8 KV, DE 100 AMP, MARCA NOJA O ROCKWILL | I11: REEMPLAZO DE RECONECTADOR 13,8 KV EN LA SALIDA DEL CIRCUITO 13,8 KV GUARACAYAL | J11: D205 | K11: PENDIENTE | L11: ALTA | M11: PZA | N11: 1 | O11: DEL 02-03-2026 AL 31-12-2026
A12: 11 | B12: ORIENTAL | C12: SUCRE | D12: ESPUGA | E12: 34.5 | F12: RECONECTADOR | G12: RECONECTADOR 13,8 KV | H12: RECONECTADOR DIGITAL DE 13.8 KV, DE 100 AMP, MARCA NOJA O ROCKWILL | I12: REEMPLAZO DE RECONECTADOR 13,8 KV EN LA SALIDA DEL CIRCUITO 13,8 KV SANTA ROSA | J12: D105 | K12: RESUELTO | L12: ALTA | M12: PZA | N12: 1 | O12: 45606
A13: 12 | B13: ORIENTAL | C13: SUCRE | D13: GUARAUNO | E13: 34.5 | F13: RECONECTADOR | G13: RECONECTADOR 13,8 KV | H13: RECONECTADOR DIGITAL DE 13.8 KV, DE 150 AMP, MARCA NOJA O ROCKWILL | I13: REEMPLAZO DE RECONECTADOR 13,8 KV EN LA SALIDA DEL CIRCUITO 13,8 KV TUNAPUY | J13: D305 | K13: RESUELTO | L13: ALTA | M13: PZA | N13: 1 | O13: 45701
A14: 13 | B14: ORIENTAL | C14: SUCRE | D14: GUARAUNO | E14: 34.5 | F14: RECONECTADOR | G14: RECONECTADOR 13,8 KV | H14: RECONECTADOR DIGITAL DE 13.8 KV, DE 100 AMP, MARCA NOJA O ROCKWILL | I14: REEMPLAZO DE RECONECTADOR 13,8 KV EN LA SALIDA DEL CIRCUITO 13,8 KV GUAYANA | J14: D405 | K14: RESUELTO | L14: ALTA | M14: PZA | N14: 1 | O14: 45701
A15: 14 | B15: ORIENTAL | C15: SUCRE | D15: LOS IPURES | E15: 34.5 | F15: RECONECTADOR | G15: RECONECTADOR 13,8 KV | H15: RECONECTADOR DIGITAL DE 13.8 KV, DE 100 AMP, MARCA NOJA O ROCKWILL | I15: REEMPLAZO DE RECONECTADOR 13,8 KV EN LA SALIDA DEL CIRCUITO 13,8 KV LOS IPURES | J15: D105 | K15: RESUELTO | L15: ALTA | M15: PZA | N15: 1 | O15: 45841
A16: 15 | B16: ORIENTAL | C16: SUCRE | D16: MARIGUITAR | E16: 34.5 | F16: RECONECTADOR | G16: RECONECTADOR 13,8 KV | H16: RECONECTADOR DIGITAL DE 13.8 KV, DE 300 AMP, MARCA NOJA O ROCKWILL | I16: REEMPLAZO DE RECONECTADOR 13,8 KV EN LA SALIDA DEL CIRCUITO 13,8 KV ALIMENTOS MARGARITA | J16: D205 | K16: PENDIENTE | L16: ALTA | M16: PZA | N16: 1 | O16: DEL 02-03-2026 AL 31-12-2026
A17: 16 | B17: ORIENTAL | C17: SUCRE | D17: SAN JUAN | E17: 34.5 | F17: RECONECTADOR | G17: RECONECTADOR 13,8 KV | H17: RECONECTADOR DIGITAL DE 13.8 KV, DE 100 AMP, MARCA NOJA O ROCKWILL | I17: REEMPLAZO DE RECONECTADOR 13,8 KV EN LA SALIDA DEL CIRCUITO 13,8 KV CATUCHAL | J17: D105 | K17: PENDIENTE | L17: ALTA | M17: PZA | N17: 1 | O17: DEL 02-03-2026 AL 31-12-2026
A18: 17 | B18: ORIENTAL | C18: SUCRE | D18: SAN JUAN | E18: 34.5 | F18: RECONECTADOR | G18: RECONECTADOR 13,8 KV | H18: RECONECTADOR DIGITAL DE 13.8 KV, DE 100 AMP, MARCA NOJA O ROCKWILL | I18: REEMPLAZO DE RECONECTADOR 13,8 KV EN LA SALIDA DEL CIRCUITO 13,8 KV SAN JUAN | J18: D305 | K18: PENDIENTE | L18: ALTA | M18: PZA | N18: 1 | O18: DEL 02-03-2026 AL 31-12-2026
A19: 18 | B19: ORIENTAL | C19: SUCRE | D19: SANTA CRUZ | E19: 34.5 | F19: RECONECTADOR | G19: RECONECTADOR 13,8 KV | H19: RECONECTADOR DIGITAL DE 13.8 KV, DE 100 AMP, MARCA NOJA O ROCKWILL | I19: REEMPLAZO DE RECONECTADOR 13,8 KV EN LA SALIDA DEL CIRCUITO 13,8 KV SANTA CRUZ | J19: D305 | K19: RESUELTO | L19: ALTA | M19: PZA | N19: 1 | O19: 45671
A20: 19 | B20: ORIENTAL | C20: SUCRE | D20: YAGUARAPARO | E20: 34.5 | F20: RECONECTADOR | G20: RECONECTADOR 13,8 KV | H20: RECONECTADOR DIGITAL DE 13.8 KV, DE 100 AMP, MARCA NOJA O ROCKWILL | I20: REEMPLAZO DE RECONECTADOR 13,8 KV EN LA SALIDA DEL CIRCUITO 13,8 KV YAGUARAPARO | J20: D205 | K20: RESUELTO | L20: ALTA | M20: PZA | N20: 1 | O20: 45704
A21: 20 | B21: ORIENTAL | C21: SUCRE | D21: SANTA CRUZ | E21: 34.5 | F21: TRANSFORMADORDEPOTENCIA | G21: ACEITE DIELECTRICO | H21: ACEITE DIELECTRICO CON UN NIVEL DE AISLAMIENTO SUPERIOR A LOS 42 KV | I21: REPOSICIÓN DE ACEITE DIELÉCTRICO A TRANSFORMADOR DE POTENCIA DE LA SUBESTACIÓN | J21: 0 | K21: RESUELTO | L21: ALTA | M21: TB | N21: 8 | O21: 46058
A22: 21 | B22: ORIENTAL | C22: SUCRE | D22: EL LOCO | E22: 34.5 | F22: TRANSFORMADORDEPOTENCIA | G22: ACEITE DIELECTRICO | H22: ACEITE DIELECTRICO CON UN NIVEL DE AISLAMIENTO SUPERIOR A LOS 42 KV | I22: REPOSICIÓN DE ACEITE DIELÉCTRICO A TRANSFORMADOR DE POTENCIA DE LA SUBESTACIÓN | J22: 0 | K22: PENDIENTE | L22: ALTA | M22: TB | N22: 8 | O22: DEL 02-03-2026 AL 31-12-2026
A23: 22 | B23: ORIENTAL | C23: SUCRE | D23: ESPUGA | E23: 34.5 | F23: TRANSFORMADORDEPOTENCIA | G23: ACEITE DIELECTRICO | H23: ACEITE DIELECTRICO CON UN NIVEL DE AISLAMIENTO SUPERIOR A LOS 42 KV | I23: REPOSICIÓN DE ACEITE DIELÉCTRICO A TRANSFORMADOR DE POTENCIA DE LA SUBESTACIÓN | J23: 0 | K23: PENDIENTE | L23: ALTA | M23: TB | N23: 8 | O23: DEL 02-03-2026 AL 31-12-2026
A24: 23 | B24: ORIENTAL | C24: SUCRE | D24: CASANAY | E24: 34.5 | F24: INTERRUPTOR | G24: INTERRUPTOR 34,5 kV | H24: DISYUNTOR DIGITAL DE 34.5 KV, DE 400 AMP, MARCA TABLECEL | I24: REEMPLAZO DE DISYUNTOR 34,5 KV | J24: B110 | K24: PENDIENTE | L24: ALTA | M24: PZA | N24: 1 | O24: DEL 02-03-2026 AL 31-12-2026
A25: 24 | B25: ORIENTAL | C25: SUCRE | D25: CATUARO | E25: 34.5 | F25: INTERRUPTOR | G25: INTERRUPTOR 34,5 kV | H25: DISYUNTOR DIGITAL DE 34.5 KV, DE 150 AMP, MARCA TABLECEL | I25: REEMPLAZO DE DISYUNTOR 34,5 KV | J25: B110 | K25: PENDIENTE | L25: ALTA | M25: PZA | N25: 1 | O25: DEL 02-03-2026 AL 31-12-2026
A26: 25 | B26: ORIENTAL | C26: SUCRE | D26: CUMANACOA | E26: 34.5 | F26: INTERRUPTOR | G26: INTERRUPTOR 34,5 kV | H26: DISYUNTOR DIGITAL DE 34.5 KV, DE 150 AMP, MARCA TABLECEL | I26: REEMPLAZO DE DISYUNTOR 34,5 KV DEL TX DE POTENCIA N° 1 | J26: B110 | K26: RESUELTO | L26: ALTA | M26: PZA | N26: 1 | O26: 45677
A27: 26 | B27: ORIENTAL | C27: SUCRE | D27: EL LOCO | E27: 34.5 | F27: INTERRUPTOR | G27: INTERRUPTOR 34,5 kV | H27: DISYUNTOR DIGITAL DE 34.5 KV, DE 150 AMP, MARCA TABLECEL | I27: REEMPLAZO DE DISYUNTOR 34,5 KV | J27: B110 | K27: PENDIENTE | L27: ALTA | M27: PZA | N27: 1 | O27: DEL 02-03-2026 AL 31-12-2026
A28: 27 | B28: ORIENTAL | C28: SUCRE | D28: LA MOVIL DEL PEÑON | E28: 34.5 | F28: INTERRUPTOR | G28: INTERRUPTOR 34,5 kV | H28: DISYUNTOR DIGITAL DE 34.5 KV, DE 200 AMP, MARCA TABLECEL | I28: REEMPLAZO DE DISYUNTOR 34,5 KV | J28: B110 | K28: PENDIENTE | L28: ALTA | M28: PZA | N28: 1 | O28: DEL 02-03-2026 AL 31-12-2026
A29: 28 | B29: ORIENTAL | C29: SUCRE | D29: ESPUGA | E29: 34.5 | F29: INTERRUPTOR | G29: INTERRUPTOR 34,5 kV | H29: DISYUNTOR DIGITAL DE 34.5 KV, DE 100 AMP, MARCA TABLECEL | I29: REEMPLAZO DE DISYUNTOR 34,5 KV | J29: B110 | K29: PENDIENTE | L29: ALTA | M29: PZA | N29: 1 | O29: DEL 02-03-2026 AL 31-12-2026
A30: 29 | B30: ORIENTAL | C30: SUCRE | D30: GUARAUNO | E30: 34.5 | F30: INTERRUPTOR | G30: INTERRUPTOR 34,5 kV | H30: DISYUNTOR DIGITAL DE 34.5 KV, DE 110 AMP, MARCA TABLECEL | I30: REEMPLAZO DE DISYUNTOR 34,5 KV | J30: B110 | K30: PENDIENTE | L30: ALTA | M30: PZA | N30: 1 | O30: DEL 02-03-2026 AL 31-12-2026
A31: 30 | B31: ORIENTAL | C31: SUCRE | D31: CARUPANO III (LA PLANTA) | E31: 34.5 | F31: INTERRUPTOR | G31: INTERRUPTOR 34,5 kV | H31: DISYUNTOR DIGITAL DE 34.5 KV, DE 100 AMP, MARCA TABLECEL | I31: REEMPLAZO DE DISYUNTOR 34,5 KV | J31: B110 | K31: PENDIENTE | L31: ALTA | M31: PZA | N31: 1 | O31: DEL 02-03-2026 AL 31-12-2026
A32: 31 | B32: ORIENTAL | C32: SUCRE | D32: LOS IPURES | E32: 34.5 | F32: INTERRUPTOR | G32: INTERRUPTOR 34,5 kV | H32: DISYUNTOR DIGITAL DE 34.5 KV, DE 100 AMP, MARCA TABLECEL | I32: REEMPLAZO DE DISYUNTOR 34,5 KV | J32: B110 | K32: PENDIENTE | L32: ALTA | M32: PZA | N32: 1 | O32: DEL 02-03-2026 AL 31-12-2026
A33: 32 | B33: ORIENTAL | C33: SUCRE | D33: MARIGUITAR | E33: 34.5 | F33: INTERRUPTOR | G33: INTERRUPTOR 34,5 kV | H33: DISYUNTOR DIGITAL DE 34.5 KV, DE 120 AMP, MARCA TABLECEL | I33: REEMPLAZO DE DISYUNTOR 34,5 KV | J33: B110 | K33: PENDIENTE | L33: ALTA | M33: PZA | N33: 1 | O33: DEL 02-03-2026 AL 31-12-2026
A34: 33 | B34: ORIENTAL | C34: SUCRE | D34: MANZANARES 34.5KV | E34: 34.5 | F34: INTERRUPTOR | G34: INTERRUPTOR 34,5 kV | H34: DISYUNTOR DIGITAL DE 34.5 KV, DE 120 AMP, MARCA TABLECEL | I34: REEMPLAZO DE DISYUNTOR 34,5 KV | J34: B110 | K34: PENDIENTE | L34: ALTA | M34: PZA | N34: 1 | O34: DEL 02-03-2026 AL 31-12-2026
A35: 34 | B35: ORIENTAL | C35: SUCRE | D35: PERICANTAR | E35: 34.5 | F35: INTERRUPTOR | G35: INTERRUPTOR 34,5 kV | H35: DISYUNTOR DIGITAL DE 34.5 KV, DE 100 AMP, MARCA TABLECEL | I35: REEMPLAZO DE DISYUNTOR 34,5 KV | J35: B110 | K35: PENDIENTE | L35: ALTA | M35: PZA | N35: 1 | O35: DEL 02-03-2026 AL 31-12-2026
A36: 35 | B36: ORIENTAL | C36: SUCRE | D36: RIO CARIBE | E36: 34.5 | F36: INTERRUPTOR | G36: INTERRUPTOR 34,5 kV | H36: DISYUNTOR DIGITAL DE 34.5 KV, DE 300 AMP, MARCA TABLECEL | I36: REEMPLAZO DE DISYUNTOR 34,5 KV | J36: B110 | K36: PENDIENTE | L36: ALTA | M36: PZA | N36: 1 | O36: DEL 02-03-2026 AL 31-12-2026
A37: 36 | B37: ORIENTAL | C37: SUCRE | D37: RIO CARIBE | E37: 34.5 | F37: INTERRUPTOR | G37: INTERRUPTOR 34,5 kV | H37: DISYUNTOR DIGITAL DE 34.5 KV, DE 200 AMP, MARCA TABLECEL | I37: REEMPLAZO DE DISYUNTOR 34,5 KV | J37: B210 | K37: PENDIENTE | L37: ALTA | M37: PZA | N37: 1 | O37: DEL 02-03-2026 AL 31-12-2026
A38: 37 | B38: ORIENTAL | C38: SUCRE | D38: SAN JUAN | E38: 34.5 | F38: INTERRUPTOR | G38: INTERRUPTOR 34,5 kV | H38: DISYUNTOR DIGITAL DE 34.5 KV, DE 100 AMP, MARCA TABLECEL | I38: REEMPLAZO DE DISYUNTOR 34,5 KV | J38: B110 | K38: PENDIENTE | L38: ALTA | M38: PZA | N38: 1 | O38: DEL 02-03-2026 AL 31-12-2026
... A40: 39 | B40: ORIENTAL | C40: SUCRE | D40: YAGUARAPARO | E40: 34.5 | F40: INTERRUPTOR | G40: INTERRUPTOR 34,5 kV | H40: DISYUNTOR DIGITAL DE 34.5 KV, DE 250 AMP, MARCA TABLECEL | I40: REEMPLAZO DE DISYUNTOR 34,5 KV | J40: B110 | K40: PENDIENTE | L40: ALTA | M40: PZA | N40: 1 | O40: DEL 02-03-2026 AL 31-12-2026
A41: 40 | B41: ORIENTAL | C41: SUCRE | D41: SANTA CRUZ | E41: 34.5 | F41: TRANSFORMADORDEPOTENCIA | G41: SOBRE CARGA MAS 100% (SUSTITUCION) | H41: TRANSFORMADOR DE POTENCIA DE 5 O 10 MVA, 34,5/13,8 KV PARA AUMENTAR LA CAPACIDAD INSTALADA DE LA SUBESTACIÓN | I41: SUSTITUIR EL TRANSFORMADOR DE POTENCIA ACTUAL DE 3MVA POR UNO DE MAYOR CAPACIDAD | J41: 0 | K41: PENDIENTE | L41: MEDIA | M41: PZA | N41: 1 | O41: DEL 02-03-2026 AL 31-12-2026
...

Sheet MATERIAL  POR ACTIVIDAD
A1: IDENTIFICADOR EQUIPO O COMPONENTE A NORMALIZAR | B1: REGION | C1: ESTADO | D1: NOMBRE SUBESTACIÓN | E1: NIVEL TENSION ENTRADA | F1: COMPONENTE DE LA SUBESTACION | G1: TIPO DE EQUIPO O ELEMENTO A NORMALIZAR EN LA SUBESTACION | H1: FAMILIA DE MATERIAL | I1: DESCRIPCION DEL MATERIAL | J1: UNIDAD | K1: PRECIO UNITARIO (Euros) | L1: CANTIDAD SOLICITADA | M1: P x Q | N1: ESTATUS | O1: N° DE PRIORIDAD
A2: 1 | B2: ORIENTAL | C2: SUCRE | D2: ARAYA | E2: 34.5 | F2: TRANSFORMADORDEPOTENCIA | G2: REQUIERE ACEITE DIELECTRICO PARA PUESTA EN SERVICIO | H2: ACEITEDIELECTRICO | I2: ACEITE DIELECTRICO | J2: =IFERROR(VLOOKUP(I2,PRECIOS!$A$2:$C$4333,2,0),"") -> TB | K2: =IFERROR(VLOOKUP(I2,PRECIOS!$A$2:$C$4333,3,0),"0") -> 780 | L2: 15 | M2: =+K2*L2 -> 11700 | N2: RESUELTO | O2: ALTA
A3: 2 | B3: ORIENTAL | C3: SUCRE | D3: ARAYA | E3: 34.5 | F3: INTERRUPTOR | G3: INTERRUPTOR 34,5 kV | H3: INTERRUPTORES | I3: INTERRUPTOR POTE VACIO 34.5 KV SF6 1250A LLEGADA | J3: =IFERROR(VLOOKUP(I3,PRECIOS!$A$2:$C$4333,2,0),"") -> UND | K3: =IFERROR(VLOOKUP(I3,PRECIOS!$A$2:$C$4333,3,0),"0") -> 54000 | L3: 1 | M3: =+K3*L3 -> 54000 | N3: PENDIENTE | O3: ALTA
A4: 3 | B4: ORIENTAL | C4: SUCRE | D4: ARAYA | E4: 34.5 | F4: RECONECTADOR | G4: RECONECTADOR 13,8 KV | H4: RECONECTADORES | I4: RECONECTADOR VACIO 13.8KV 110KV 560A | J4: =IFERROR(VLOOKUP(I4,PRECIOS!$A$2:$C$4333,2,0),"") -> UND | K4: =IFERROR(VLOOKUP(I4,PRECIOS!$A$2:$C$4333,3,0),"0") -> 10908 | L4: 1 | M4: =+K4*L4 -> 10908 | N4: PENDIENTE | O4: ALTA
A5: 4 | B5: ORIENTAL | C5: SUCRE | D5: CASANAY | E5: 34.5 | F5: RECONECTADOR | G5: RECONECTADOR 13,8 KV | H5: RECONECTADORES | I5: RECONECTADOR VACIO 13.8KV 110KV 560A | J5: =IFERROR(VLOOKUP(I5,PRECIOS!$A$2:$C$4333,2,0),"") -> UND | K5: =IFERROR(VLOOKUP(I5,PRECIOS!$A$2:$C$4333,3,0),"0") -> 10908 | L5: 1 | M5: =+K5*L5 -> 10908 | N5: RESUELTO | O5: ALTA
A6: 5 | B6: ORIENTAL | C6: SUCRE | D6: CATUARO | E6: 34.5 | F6: RECONECTADOR | G6: RECONECTADOR 13,8 KV | H6: RECONECTADORES | I6: RECONECTADOR VACIO 13.8KV 110KV 560A | J6: =IFERROR(VLOOKUP(I6,PRECIOS!$A$2:$C$4333,2,0),"") -> UND | K6: =IFERROR(VLOOKUP(I6,PRECIOS!$A$2:$C$4333,3,0),"0") -> 10908 | L6: 1 | M6: =+K6*L6 -> 10908 | N6: PENDIENTE | O6: ALTA
A7: 6 | B7: ORIENTAL | C7: SUCRE | D7: CATUARO | E7: 34.5 | F7: RECONECTADOR | G7: RECONECTADOR 13,8 KV | H7: RECONECTADORES | I7: RECONECTADOR VACIO 13.8KV 110KV 560A | J7: =IFERROR(VLOOKUP(I7,PRECIOS!$A$2:$C$4333,2,0),"") -> UND | K7: =IFERROR(VLOOKUP(I7,PRECIOS!$A$2:$C$4333,3,0),"0") -> 10908 | L7: 1 | M7: =+K7*L7 -> 10908 | N7: PENDIENTE | O7: ALTA
A8: 7 | B8: ORIENTAL | C8: SUCRE | D8: CUMANACOA | E8: 34.5 | F8: RECONECTADOR | G8: RECONECTADOR 13,8 KV | H8: RECONECTADORES | I8: RECONECTADOR VACIO 13.8KV 110KV 560A | J8: =IFERROR(VLOOKUP(I8,PRECIOS!$A$2:$C$4333,2,0),"") -> UND | K8: =IFERROR(VLOOKUP(I8,PRECIOS!$A$2:$C$4333,3,0),"0") -> 10908 | L8: 1 | M8: =+K8*L8 -> 10908 | N8: RESUELTO | O8: ALTA
A9: 8 | B9: ORIENTAL | C9: SUCRE | D9: CUMANACOA | E9: 34.5 | F9: RECONECTADOR | G9: RECONECTADOR 13,8 KV | H9: RECONECTADORES | I9: RECONECTADOR VACIO 13.8KV 110KV 560A | J9: =IFERROR(VLOOKUP(I9,PRECIOS!$A$2:$C$4333,2,0),"") -> UND | K9: =IFERROR(VLOOKUP(I9,PRECIOS!$A$2:$C$4333,3,0),"0") -> 10908 | L9: 1 | M9: =+K9*L9 -> 10908 | N9: PENDIENTE | O9: ALTA
A10: 9 | B10: ORIENTAL | C10: SUCRE | D10: EL LOCO | E10: 34.5 | F10: RECONECTADOR | G10: RECONECTADOR 13,8 KV | H10: RECONECTADORES | I10: RECONECTADOR VACIO 13.8KV 110KV 560A | J10: =IFERROR(VLOOKUP(I10,PRECIOS!$A$2:$C$4333,2,0),"") -> UND | K10: =IFERROR(VLOOKUP(I10,PRECIOS!$A$2:$C$4333,3,0),"0") -> 10908 | L10: 1 | M10: =+K10*L10 -> 10908 | N10: PENDIENTE | O10: ALTA
A11: 10 | B11: ORIENTAL | C11: SUCRE | D11: EL LOCO | E11: 34.5 | F11: RECONECTADOR | G11: RECONECTADOR 13,8 KV | H11: RECONECTADORES | I11: RECONECTADOR VACIO 13.8KV 110KV 560A | J11: =IFERROR(VLOOKUP(I11,PRECIOS!$A$2:$C$4333,2,0),"") -> UND | K11: =IFERROR(VLOOKUP(I11,PRECIOS!$A$2:$C$4333,3,0),"0") -> 10908 | L11: 1 | M11: =+K11*L11 -> 10908 | N11: PENDIENTE | O11: ALTA
A12: 11 | B12: ORIENTAL | C12: SUCRE | D12: ESPUGA | E12: 34.5 | F12: RECONECTADOR | G12: RECONECTADOR 13,8 KV | H12: RECONECTADORES | I12: RECONECTADOR VACIO 13.8KV 110KV 560A | J12: =IFERROR(VLOOKUP(I12,PRECIOS!$A$2:$C$4333,2,0),"") -> UND | K12: =IFERROR(VLOOKUP(I12,PRECIOS!$A$2:$C$4333,3,0),"0") -> 10908 | L12: 1 | M12: =+K12*L12 -> 10908 | N12: RESUELTO | O12: ALTA
A13: 12 | B13: ORIENTAL | C13: SUCRE | D13: GUARAUNO | E13: 34.5 | F13: RECONECTADOR | G13: RECONECTADOR 13,8 KV | H13: RECONECTADORES | I13: RECONECTADOR VACIO 13.8KV 110KV 560A | J13: =IFERROR(VLOOKUP(I13,PRECIOS!$A$2:$C$4333,2,0),"") -> UND | K13: =IFERROR(VLOOKUP(I13,PRECIOS!$A$2:$C$4333,3,0),"0") -> 10908 | L13: 1 | M13: =+K13*L13 -> 10908 | N13: RESUELTO | O13: ALTA
... A54: 53 | B54: ORIENTAL | C54: SUCRE | D54: SAN JUAN | E54: 34.5 | F54: RECONECTADOR | G54: RECONECTADOR 13,8 KV | H54: RECONECTADORES | I54: RECONECTADOR VACIO 13.8KV 110KV 560A | J54: =IFERROR(VLOOKUP(I54,PRECIOS!$A$2:$C$4333,2,0),"") -> UND | K54: =IFERROR(VLOOKUP(I54,PRECIOS!$A$2:$C$4333,3,0),"0") -> 10908 | L54: 1 | M54: =+K54*L54 -> 10908 | N54: PENDIENTE | O54: ALTA

Sheet LISTA
A1: FAMILIAS | C1: REGION | E1: CAPITAL | F1: GUAYANA | G1: LOS_ANDES | H1: ORIENTAL | I1: LOS_LLANOS | J1: CENTRAL | K1: INSULAR | L1: OCCIDENTAL | N1: CATEGORIA | P1: UNIDAD | R1: TENSIONSUBESTACION | T1: TENSIONCIRCUITO | V1: TIPORESTRICCIONES | X1: COMPONENTES | Z1: SERVICIOSAUXILIARES | AA1: INTERRUPTOR | AB1: SEGURIDADINFRAESTRUCTURA | AC1: TABLERODECONTROLYMEDICIÓN | AD1: TRANSFORMADORDEPOTENCIA | AE1: SUBESTACIONMOVIL | AF1: BARRAS | AG1: SECCIONADOR | AH1: PARARRAYO | AI1: ESTRUCTURASDESOPORTE | AJ1: TRANSFORMADORESDEMEDICION | AK1: BANCODECAPACITORES | AL1: BOBINAS | AM1: SISTEMADEPUESTAATIERRA | AN1: REGULADOR | AO1: RECONECTADOR | AP1: CORTACORRIENTE | AQ1: REACTOR | AR1: AISLADORESSOPORTE | AS1: CONDUCTOR | AT1: CONECTOR | AU1: HERRAJE | AV1: MANTENIMIENTOPREVENTIVO | AX1: ESTATUS
A2: AISLADORES Y COPAS | C2: CAPITAL | E2: CAPITAL | F2: AMAZONAS | G2: MERIDA | H2: ANZOATEGUI | I2: APURE | J2: ARAGUA | K2: NUEVA ESPARTA | L2: FALCON | N2: ADMINISTRACION DE CARGA | P2: PZA | R2: 400 | T2: 2.4 | V2: AISLAMIENTO | X2: AISLADORES_SOPORTE | Z2: BATERÍAS | AA2: INTERRUPTOR 12,47 kV | AB2: AIRE ACONDICIONADO | AC2: SISTEMAS DE CONTROL | AD2: FUERA DE SERVICIO RECUPERABLE (SUSTITUCION) | AE2: FUERA DE SERVICIO RECUPERABLE (SUSTITUCION) | AF2: BARRAS LADO DE ALTA | AG2: SECCIONADORES DE 34,5 KV | AH2: PARARRAYOS DE 13,8 kV | AI2: ESTRUCTURAS DE SOPORTE | AJ2: TRANSFORMADORES DE TENSION | AK2: BANCO DE CAPACITORES | AL2: BOBINAS | AM2: BARRAS | AN2: REGULADORES DE TENSION | AO2: RECONECTADOR 34,5 KV | AP2: CORTACORRIENTE 13,8 KV | AQ2: REACTOR | AR2: AISLADORES SOPORTE | AS2: CONDUCTOR | AT2: CONECTOR | AU2: HERRAJE | AV2: PUESTA A TIERRA | AX2: PENDIENTE
A3: CABLES Y CONDUCTORES | C3: GUAYANA | E3: LA GUAIRA | F3: BOLIVAR | G3: TACHIRA | H3: MONAGAS | I3: BARINAS | J3: CARABOBO | L3: LARA | N3: ALUMBRADO | P3: kg | R3: 230 | T3: 4.16 | V3: CONDENSADOR | X3: BANCO_DE_CAPACITORES | Z3: CARGADOR DE BATERIAS | AA3: INTERRUPTOR 13,8 kV | AB3: ALUMBRADO EXTERNO | AC3: SEÑALIZACIÓN Y ALARMAS | AD3: FUERA DE SERVICIO NO RECUPERABLE (SUSTITUCION) | AE3: FUERA DE SERVICIO NO RECUPERABLE (SUSTITUCION) | AF3: BARRAS LADO DE BAJA | AG3: SECCIONADORES DE 13,8 KV | AH3: PARARRAYOS DE 34,5 kV | AJ3: TRANSFORMADORES DE CORRIENTE | AK3: ACCESORIOS PARA LA INSTALACION | AM3: CONDUCTOR PARA A TIERRA | AO3: RECONECTADOR 13,8 KV | AP3: CORTACORRIENTE 34,5 KV | AS3: TRAMO AEREO | AU3: POSTE | AV3: DIAGNÓSTICO TERMOGRÁFICO | AX3: EN EJECUCION
A4: CONECTORES | C4: LOS_ANDES | E4: MIRANDA | F4: DELTA AMACURO | G4: TRUJILLO | H4: SUCRE | I4: COJEDES | J4: YARACUY | L4: ZULIA | N4: CALIDAD DE SERVICIO | P4: m | R4: 138 | T4: 4.8 | V4: CONECTORES | X4: BARRAS | Z4: EQUIPOS DE PROTECCIÓN. | AA4: INTERRUPTOR 24 kV | AB4: ALUMBRADO INTERNO | AC4: TELEMANDOS | AD4: SOBRE CARGA MAS 100% (SUSTITUCION) | AE4: SOBRE CARGA MAS 100% (SUSTITUCION) | AF4: BARRAS | AG4: SECCIONADORES DE LINEA | AH4: PARARRAYOS DE 30 kV | AJ4: CONDUCTOR DE CONTROL | AM4: SISTEMA DE PUESTA A TIERRA | AO4: RECONECTADOR 30 KV | AP4: CORTACORRIENTE BARRA | AS4: TRAMO SUBTERRANEO | AV4: INFRAESTRUCTURA Y PERÍMETRO | AX4: RESUELTO
A5: CORTACORRIENTES | C5: ORIENTAL | I5: GUARICO | N5: ELECTRIFICACION O FUERA DE RED | P5: RL | R5: 115 | T5: 6.9 | V5: EQUIPOS DE SECCIONAMIENTO O INTERCONEXION | X5: BOBINAS | Z5: EXTRATORES | AA5: INTERRUPTOR 30 kV | AB5: CERCA PERIMETRAL | AC5: COMUNICACIONES | AD5: OPERATIVO REQUIERE SUSTITUCION | AE5: REQUIERE MANTENIMIENTO MAYOR PARA PUESTA EN SERVICIO | AG5: SECCIONADORES DE BARRA | AH5: PARARRAYO LADO DE ALTA | AM5: BARRAS COPERWEL | AO5: RECONECTADOR 12,47 KV | AP5: CORTACORRIENTE 12,47 KV | AV5: MANTENIMIENTO DE EQUIPOS AUXILIARES
A6: EQUIPOS DE SUB ESTACIONES | C6: LOS_LLANOS | I6: PORTUGUESA | N6: ESTRUCTURA O POSTE | P6: UND | R6: 69 | T6: 8.3 | V6: ESTRUCTURA | X6: CONECTORES | Z6: MOTORES DE CONTROL | AA6: INTERRUPTOR 34,5 kV | AB6: DESMALEZAMIENTO DE LA SUBESTACION | AD6: REQUIERE MANTENIMIENTO MAYOR PARA PUESTA EN SERVICIO | AE6: REQUIERE MANTENIMIENTO MENOR PARA PUESTA EN SERVICIO | AG6: SECCIONADORES DE PUESTA A TIERRA | AH6: PARARRAYO LADO DE BAJA | AM6: CONECTORES | AO6: RECONECTADOR 24 KV | AV6: MUESTRA DE ACEITE DIELÉCTRICO
A7: FUSIBLES | C7: CENTRAL | N7: NO PROCEDE, OTRO SERVICIO | P7: H-H | R7: 34.5 | T7: 11.9 | V7: LINEAS CABLES O CONDUCTORES | X7: CORTACORRIENTE | Z7: PLANTA DE EMERGENCIA | AA7: INTERRUPTOR DE PROTECCION DE CIRCUITO | AB7: IMPERMEABILIZACION | AD7: REQUIERE MANTENIMIENTO MENOR PARA PUESTA EN SERVICIO | AG7: SECCIONADORES DE DERIVACION | AO7: CAJA DE CONTROL DE RECONECTADOR | AV7: NECESIDADES DE LA PIEDRA PICADA
A8: HERRAJES | C8: INSULAR | N8: PICA Y PODA | P8: litro | R8: 30 | T8: 12.47 | V8: OTROS | X8: ESTRUCTURAS_DE_SOPORTE | Z8: RECTIFICADORES | AA8: INTERRUPTOR DE PROTECCION DE TRX DE POTENCIA | AB8: NECESIDADES DE LA PIEDRA PICADA | AD8: REQUIERE ADECUACIONES PARA INSTALARSE | AO8: TARJETA PARA RECONECTADOR | AV8: ILUMINACIÓN DE LA SE
A9: INTERRUPTORES | C9: OCCIDENTAL | N9: RECLAMO DE SERVICIO | P9: TB | R9: 23.9 | T9: 13.8 | V9: PROTECCIONES | X9: INTERRUPTOR | Z9: TRANSFORMADOR DE LOS SERVICIOS AUXILIARES | AA9: INTERRUPTOR DE PROTECCION DE TRX DE SERVICIOS AUXILIARES | AB9: SISTEMA CONTRA INCENDIO | AD9: REQUIERE ACEITE DIELECTRICO PARA PUESTA EN SERVICIO | AO9: BATERIA DEL RECONECTADOR | AV9: APLICACIÓN DE TRATAMIENTO QUIMICO
A10: PARARRAYOS | N10: TRANSFORMADOR | P10: m2 | R10: 13.8 | T10: 23.9 | V10: REGULADORES DE VOLTAJE | X10: MANTENIMIENTO PREVENTIVO | AA10: INTERRUPTORES DE ENLACE DE BARRA | AV10: PRUEBAS A RELES DE PROTECCIONES EN SS/EE
A11: POSTES | N11: SOLICITUD DE MEDIDOR | P11: m3 | R11: 12.47 | T11: 24 | V11: SEGURIDAD | X11: PARARRAYO | AV11: FUNCIONAMIENTO DE REMOTAS (COMUNICACIÓN)
A12: RECONECTADORES | N12: SOLIICTUD DE FACTURA | R12: 7.5 | T12: 24.5 | X12: REACTOR | AV12: OTROS
A13: REGULADORES | N13: REQUIERE DE MANTENIMIENTO | R13: 4.8 | T13: 30 | X13: RECONECTADOR
A14: SECCIONADORES | N14: OTRO REQUERIMIENTO | R14: NO LISTADA | T14: 34.5 | X14: REGULADOR
A15: TEIPES CINTAS Y OTROS AISLANTES | T15: NO LISTADA | X15: SECCIONADOR
A16: TRANSFORMADORES | X16: SEGURIDAD_INFRAESTRUCTURA
A17: TRANSFORMADORES DE MEDIDA (TC Y TP) | X17: SERVICIOS_AUXILIARES
A18: MATERIALES VARIOS | X18: SISTEMA_DE_PUESTA_A_TIERRA
A19: MATERIALES ALUMBRADO PUBLICO | X19: SUBESTACION_MOVIL
A20: RECTIFICADORES | X20: TABLERO_DE_CONTROL_Y_MEDICIÓN
A21: BANCO DE BATERIAS | X21: TRANSFORMADOR_DE_POTENCIA
A22: NO REQUIERE MATERIAL | X22: TRANSFORMADORES_DE_MEDICION

Sheet FAMILIAS
A1: AISLADORES_Y_COPAS | B1: ACEITEDIELECTRICO | C1: MATERIALES_ALUMBRADO_PUBLICO | D1: CABLES_Y_CONDUCTORES | E1: CONECTORES | F1: CORTACORRIENTES | G1: FUSIBLES | H1: HERRAJES | I1: INTERRUPTORES | J1: PARARRAYOS | K1: POSTES | L1: RECONECTADORES | M1: REGULADORES | N1: SECCIONADORES | O1: TEIPES_CINTAS_Y_OTROS_AISLANTES | P1: TRANSFORMADORES | Q1: TRANSFORMADORESDEPOTENCIA | R1: EQUIPOSDESUBESTACIONES | S1: BANCODECONDESADORES | T1: TRANSFORMADORES_DE_MEDIDA | U1: MATERIALES_VARIOS | V1: RECTIFICADORES | W1: BANCO_DE_BATERIAS | X1: NO_REQUIERE_MATERIAL
A2: AISLADOR DE SUSPENSION 7,5 KV, DE PORCEL | B2: ACEITE DIELECTRICO | C2: IGNITOR LAMP VAP NA 208/240V 400W | D2: CABLE CU CONCENTR 8AWG 1P 600V PVC-MALLA | E2: CONECTOR COMP CUÑA COBRE 2/0 A 2/0AWG | F2: CORTACORRIENTE MONOP 13.8KV 100A 12KA | G2: FUSIBLE CARTUCHO T/NH 125A 500V TAMAÑO 1 | H2: PERNOS CARRUAJE 5/8" X 1 3/4" | I2: INT TRANSF/AUT VACIO 3F 600A 15KV BASICO | J2: DESCARGADOR DE SOBRETENSION 21 KV | K2: POSTE METALICO HEX. DE ALTURA HP 10 MTS | L2: RECONECTADOR DE POTENCIA 24 KV | M2: REGULADOR TENSION MONOF 552KVA 13.8KV | N2: SECCIONADOR MONOP 13.8KV 630A 110KVBIL | O2: CINTA MALLA DE COBRE ESTAÑADO | P2: TDI 1F 7200-4800V/120-240 V 100 KVA | Q2: TRANSF. DE POTENCIA 23,9/8 kV 15 MVA | R2: COMUNICACIONES | S2: BANCO DE CAPACITADORES DORES3X50KVA | T2: TRANSFORMADORES DE CORRIENTE | U2: CANDADO | V2: CARGADOR RECTIFICADOR 120 CA a 120 CC CON ECUALIZADOR DE HASTA 8 horas. | W2: BATERÍAS EN GEL DE 2,2 V | X2: NO REQUIERE MATERIAL
A3: AISLADOR DE ESPIGA PARA 15 KV | C3: IGNITOR P/LUMINARIA NA 100 W | D3: CABLE AL, TTU NO. 500 MCM | E3: CONECTOR COMPRESION AUTOMATICO 1/0AWG | F3: CORTACORRIENTE MONOP 34.5KV 100A 8KA | G3: FUSIBLE CARTUCHO T/NH 63A 500V TAMAÑO 1 | H3: ABRAZADERA 4 -4 1/2" X 3/8"REFORZADO | I3: INTERRUP POT VACIO 13,8 KV SF6 1250A | J3: PARARRAYO POLIME 36KV 10KA 660MM OXIDO | K3: BRAZO TIPO LATIGO DOBLE DE 2,40 MTS | L3: RECONECTADOR VACIO 13.8 KV 110KV 560A | M3: REGULADOR TENSION MONOF 333KVA 34.5KV | N3: SECCIONADOR MONOP 34.5KV 630A 170KVBIL | O3: CINTA AISL PVC 3/4"X 66 AMAR 3M #33 | P3: TRF INTEMP 1F 25KVA 4800X7200V-120/240V | Q3: TRANSF. DE POTENCIA 34,5/13,8 kV 10 MVA | R3: SEÑALIZACIÓN Y ALARMAS | T3: TRANSFORMADORES DE TENSION | U3: RADIADORES Y EMPACADURAS DE BUSHINGS | V3: ENT. TRIF. 208,0 VAC, SAL. 120 VDC , 100 A-H | W3: BANCO DE BATERIAS (60 BATERIAS DE 2,2 V) TIPO GEL DE 40 Ah 12V.
A4: AISLADOR POLIMERICO SUSP DIST AG 23,9KV | C4: IGNITOR LAMP VAP NA 120V 150W | D4: CABLE AL, TTU NO. 4/0 AWG | E4: CONECTOR TIPO TORNILLO BRONCE "U" KS-23 (6-2 / 14) AWG. | F4: CORTACORRIENTE MONOP 13.8KV 100A 12KA TIPO B | G4: FUSIBLE CARTUCHO T/NH 100A 500V TAMAÑO 1 | H4: CRUCETAS DE ACERO GALVANIZADO | I4: INTERRUP POT VACIO 34,5 KV SF6 630A | J4: PARARRAYO POLIMERICO 17.5KV 10KA DF=606 | K4: BRAZO TIPO LATIGO SENCILLO DE 2,40 MTS | L4: RECONECTADOR VACIO 34,5 KV 150 KV 560A | M4: REGULADOR TENSION MONOF 276KVA 13.8KV | N4: SECCIONADOR MONOPOLAR 23.9 KV 600A | O4: CINTA 1/2" POLIESTER REFORZ FILAM.VIDRIO | P4: TDI 1F 7200-4800/120-240V 50 KVA | Q4: TRANSF. DE POTENCIA 34,5/13,8 kV 20 MVA | R4: CUBICULO DE PROTECCION DE ALARMAS | U4: ACEITE DIELECTRICO | W4: BATERIA DE 96 VOLTIOS DC
A5: AISLADOR SUSP POLIM 17.5KV DF360MM 45KN | C5: BALASTO DE 100W NA 120V REACTOR | D5: CABLE AL, TTU NO. 1/0 AWG | E5: CONECTOR CU-AL TIPO "U" KSU-25 2-1/0 | F5: PORTAFUSIBL CORTACORR 15KV "C" 125KVB | G5: FUSIBLE D/EXPULSION T/E 100A 15KV | H5: MALLA ESTAÑADA#8 | I5: INTERRUPTOR TRANS/AUT VACIO 3F 600ª 15KV BASICO | J5: DESCARGADOR SOBRETENSION POLIMERICO 6KV | K5: BRAZO CORTO 0,80 MTS | M5: REGULADOR TENSION MONOF 833KVA 34.5KV | N5: SECCIONADOR TRIPOLAR 13.8KV 630A 110KBIL | O5: CINTA AISLANTE GOMA 3/4" ANCH AT NEG #23 | P5: TRF SUM 1F 4800X7200V-120/240V 50KVA | Q5: TRANSF. DE POTENCIA 34,5/13,8 kV 25 MVA | R5: SISTEMAS DE CONTROL | U5: ANALOGICO | V5: Rectificador Voltaje de Entrada: 208 [Vac]. Corriente nominal 65 A. Salida: 125 [Vdc]. 100[A]. | W5: BATERIAS 125 Vcc 40 AH.
A6: AISL.SUSP POLIMERICO 36KV 760MM 45KN | C6: BALASTO LUMINARIA V/S 150W 110/120V | D6: CABLE AL, TTU NO. 2 AWG | E6: CONECTOR CU-AL TIPO "U" KSU-26 2-2/0A | F6: CORTACORRIENTE MONOPOLAR 23,9 KV | G6: FUSIBLE D/EXPULSION T/E 125A 15KV | H6: PERNOS CARRUAJE 5/8" X 4" | I6: INTERRUPTOR DE POTENCIA 24KV | J6: PARARRAYO CERAMICA TIPO PEDESTAL PARA SUBESTACION DE 15KV | K6: ESTRUCTURA 2 X 45' 5 1/2" | L6: CAJA DE CONTROL RECONECTADOR NOJA | M6: Regulador de voltaje monofásico tipo VR-32 (32 pasos), +/- 10%, 34500 V Y - 19920 V Delta, 60 Hz Rise, 55/65C Rise, 200 kVA, 100/112 A. Incluye bypass switch. | N6: SECCIONAD 3F TR/MAN 2V 15KV 600A SF6 | O6: CINTA RELLENO 1-1/2" X 5' X 1/8" | P6: TRF SUM 1F 4800X7200V-120/240V 100KVA | Q6: TRANSF. DE POTENCIA 34,5/13,8 kV 30 MVA | R6: TELEMANDOS | U6: ANTENA Y EQUIPOS DE COMUNICACIÒN | W6: BATERIA DE 12V 7A
A7: AISLADOR CARRETE PERCHA 53.2CL | C7: BALASTO P/LAMP DE V/SODIO 150W 208-240V | D7: CABLE AL, TTU NO. 4 AWG | E7: CONECTOR CU-AL TIPO "U" KSU-29 250MCM | F7: PORTA FUSIBLE P/CORTAC 34.5KV 150 BILL | G7: FUSIBLE D/EXPULSION T/E 20A 15KV | H7: SOPORTE PARA CORTACORRIENTE Y PARARRAYO (Z) | I7: INTERRUPTOR POTE VACIO 13.8 KV SF6 2000A | J7: PARARRAYO CERAMICA TIPO PEDESTAL PARA SUBESTACION DE 34.5KV | K7: ESTRUCTURA 2 X 40' 4 1/2" | L7: RECONECTADO 13,8 KV, 650A | M7: REGULADOR DE 333 KVA VOLTAJE 7600/13200Y | N7: SECCIONAD 3F TR/MAN 3V 15KV 600A SF6 | O7: CINTA SEMICONDUCT 3/4" X 0030" X 15 # 13 | P7: TRF SUM 1F 4800X7200V-120/240V 167KVA | Q7: TRANSF. DE POTENCIA 34,5/13,8 kV 40 MVA | R7: RELE MULTIFUCION NUMERICO | U7: CERCA PERIMETRAL | W7: BATERIA DE 12 VOLTIO 12 AMPERIO, F1 TERMINAL MEDIDAS 15X98X95MM
A8: COPA TERM/TERM/CALIEN/EXTER 4-1/0 15KV | C8: BALASTO P/LUMIN. 250W NA/208/240V | D8: CABLE CUADRUPLEX NO. 2 AWG | E8: CONECTOR COMPRESION AUTOMATICO 2AWG | F8: PORTAFUSIBLE 100 A, 23,9 KV, CUT OUT | G8: FUSIBLE D/EXPULSION T/E 30A 15KV | H8: TORNILLO ACERO GALVANIZADO 5/8" X 1 3/4" | I8: INTERRUPTOR POTE VACIO 34.5 KV SF6 1250A | J8: PARARRAYO POLIME 36KV 10KA 660MM OXIDO | K8: ESTRUCTURA 2 X 36' 4 1/2" | M8: CONDENS AT 1F INTEMP 50KVAR 2770V75KV BIL | N8: SECCIONAD 3F TR/MAN 4V 15KV 600A SF6 | O8: CINTA AISLANTE ELECTRICA N° 35 (COLORES PARA IDENTIFICAR FASES). | P8: TRF SUM 1F 4800X7200V-120/240V 250KVA | Q8: TRANSF. DE POTENCIA 30/12,47 kV 20 MVA | R8: AIRE ACONDICIONADO 24000 BTU, 220 V | U8: CONCRETO 180 KG/CM2 | W8: CARGADOR DE BATERIAS MARCA JUNPEER O SIMILAR
A9: COPA TERM/TERM/CALI/EXTER 2/0-350MCM15KV | C9: BALASTO LUMIN VAP NA 208/240V 400W | D9: CABLE TRIPLEX NO. 2 AWG | E9: CONECTOR COMPRESION AUTOMATICO 2/0AWG | G9: FUSIBLE D/EXPULSION T/E 40A 15KV | H9: ABRAZADERA 3 1X 3 1/2"X 3/4" | I9: INTERRUPTOR POTENCIA VACIO 13,8 KV SF6 1250A | J9: DESCARGADOR SOBRETENSION POLIMERICO 9KV | K9: ESTRUCTURA 2 X 27' 3 1/2" | L9: TARJETA DE CONTROL Y POTENCIA PARA RECONECTADOR | M9: CONDENS AT 1F INTEMP 60KVAR 2770V75KV BIL | N9: SECCIONAD 3F VACIO C/PORTAFUS CANISTER | O9: CINTA DE ATERRAMIENTO N° 25 | P9: TRF SUM 1F 4800X7200V-120/240V 333KVA | Q9: TRANSF. DE POTENCIA 30/12,47 kV 10 MVA | R9: BANCO DE CAPACITADORES DORES3X50KVA | U9: CONCRETO PARA BASE 210 KG/CM2 | W9: CELDAS DE 2.0 VDC, 300 A-H
A10: COPA TERMINAL 34.5KV 4/0 A 500MCM EXTER | C10: BOMBILLO MET HAL 208/240V 150W CLARA | D10: CABLE TRIPLEX NO. 6 AWG | E10: CONECTOR COMPRESION AUTOMATICO 4/0AWG | G10: FUSIBLE D/EXPULSION T/E 50A 15KV | H10: ABRAZADERA 3-3 1/2" 3 T | I10: INTERRUPTOR POTENCIA VACIO 13,8 KV SF6 2000A | J10: DESCARGADORES DE SOBRETENSIÓN 9KV | K10: POSTE ACERO 12,20M (40PIE) 30.000LBS-PIE | L10: BATERIA PARA RECONECTADOR MARCA ROSWELD, 24 V - 7AH | M10: CONDENS AT 1F INTEMP 100KVAR 2770V75KV BIL | N10: SECCIONAD 3F VACIO C/PORTAFUS PARA MCLF | O10: CINTA AISLANTE VINILO 105 °C 600 V | P10: TRF SUM 1F 4800X7200V-120/240V 500KVA | Q10: TRANSF. DE POTENCIA 34,5/13,8 kV 5 MVA | R10: CELDA DE PROTECCIONES EN 34,5 KV | U10: EXTINTOR, POLVO QUÍMICO | W10: BANCO DE BATERIAS 24 CELDAS / 48VCC INCLUIR RACK DE INSTALACION , CONECTORES Y CABLES
A11: COPA TERMINAL INTERIOR 15KV 500MCM | C11: BOMBILLO MET HAL 208/240V 250W TUBUL | D11: CABLE CU TTU NO. 750 MCM 600V | E11: CONEC T/COMP AUT CU COND N° 2AWG | G11: FUSIBLE D/EXPULSION T/E 65A 15KV | H11: ABRAZADERA 3-3 1/2" 4 T | I11: INTERRUPTOR POTENCIA VACIO 34,5 KV SF6 1250A | K11: POSTE ACERO 9.14M 266KG | L11: CAJA DE CONTROL SWITCH DE POTENCIA SIEMENS 3AD, CON RELE DE PROTECCION SIEMENS REYROLLE ARGUS-M 7SR7224 | M11: CONDENS AT 1F INTEMP 110KVAR 2770V75KV BIL | N11: SECCIONADOR SF6 T.A 2V C/SECC 600A 4.8KV | O11: CINTA AISLANTE GOMASILIC 180°C, 69 | P11: TDI 1F 13800/120-240V 25KVA | Q11: TRANSF. DE POTENCIA 34,5/13,8 KV 2,5 MVA | R11: ELECTRO VENTILADOR DE LOS TX 10MVA | U11: MALLA DE TIERRA | W11: BANCO DE BATERIAS DE 125 vcc, DE 60 CELDAS , DE 2 VOLTIOS CADA UNA. INCLUIR RACK DE INSTALACION , CONECTORES Y CABLES
A12: COPA TERMINAL INTER 15KV 1000MCM | C12: BOMBILLO MET HAL 208/240V 400W TUB CLARA | D12: CONDUCTOR AZUSA ARVIDAL 1/0AWG 7H | E12: CONECTOR COMPRESION BIMETAL 2 A 2/0AWG | G12: FUSIBLE LIMITADOR "C" 65A 15,5KV CM6 (2NX65) | H12: ABRAZADERA 4-4 1/2" 3 T | I12: INTERRUPTOR POTENCIA VACIO 34,5 KV SF6 630A | K12: POSTE A/G 11,28M EC=211KG | M12: CONDENS AT 1F INTEMP 115KVAR 2770V75KV BIL | N12: SECCIONADOR/TRAN/AUT/2V C/SECC 15KV SF6 | O12: CINTA AISLANTE GOMA 90 °C, 69.000 | P12: TRANSF 3F 13800-208Y/120V 750KVA | Q12: TRANSF. DE POTENCIA 34,5/13,8 KV 3 MVA | R12: TERMINALES PARA CONDUCTOR DE CONTROL PARA EL RELÉ | U12: PIEDRA PICADA NUM 4 Ó 5 | W12: BANCO DE BATERIAS DE 125 vcc, TIPO MONOBLOCK DE 10 CELDAS , DE 12 VOLTIOS CADA UNA. INCLUIR RACK DE INSTALACION , CONECTORES Y CABLES
A13: COPA TERMINAL EXTERIOR 15KV 500MCM | C13: LAMPARA VAPOR SODIO 120V 100W E40 | D13: CONDUCTOR ACSR 336.4 KCM 18+1H | E13: CONECTOR COMP TERM BIMETAL 2/0AWG 1AGUJ | G13: FUSIBLE LIMITADOR 12A 15,5KV CLASE C,CM5 (TIPO NX) | H13: ABRAZADERA 4-4 1/2" 4 T | I13: INTERRUPTOR 2 VIAS AISLADO EN SF6 | K13: POSTE A/G 12,20M EC=437KG | M13: CONDENS AT 1F INTEMP 200KVAR 2770V75KV BIL | N13: SIS ENCLAV P/CANISTER P/INT TR/AUT VACIO | O13: CINTA PLASTICA 3/4 | P13: TRF SUM 3F 13800-208Y/120V 500KVA | Q13: TRANSF. DE POTENCIA 34,5/13,8 KV 36 MVA | R13: TARJETA DEL CPU DEL RELÉ F-650 GENERAL ELECTRIC | U13: PINTURA ALUMINIO | W13: TERMINALES PARA CONDUCTOR DE CONTROL PARA LOS TC
A14: COPA TERM EXT USO CONV 15KV400 1000MCM | C14: LAMPARA VAPOR SODIO 220V 150W E40 | D14: CONDUCTOR DESNUDO ARVIDAL 4/0AWG 7H | E14: CONECTOR COMP TERM BIMETAL 250KCM 2AGUJ | G14: FUSIBLE LIMITADOR 18A 15,5KV CLASE C,CM5 (TIPO NX) | H14: ABRAZADERA 5-5 1/2" 3 T | I14: INTERRUPTOR 3 VIAS AISLADO EN SF6 | K14: POSTE ACERO GALVANIZADO 8.23M 116KG | M14: CONDENS 1F INTEMP 50KVAR 4800V75KV BIL 60HZ | N14: SIS ENCLAV P/MOLDEADO P/INT TR/AUT VACIO | O14: CINTA AISL PLAST 3/4" P/IDENTIF.CABLES | P14: TDI 1F 13800/120-240V 37,5KVA | Q14: TRANSF. DE POTENCIA 23,9/13,8 KV 20 MVA | R14: BUSHING PARA TRANSFORMADOR DE POTENCIA DE 8MVA EN ENTRADA DE 34,5 KV | U14: PINTURA ASFALTICA
A15: CONO ESFUERZO T/EXT 1P 15KV 2-2/0 AWG | C15: LAMPARA VAPOR SODIO 208-240V 250W E40 | D15: CONDUCTOR DESNUDO ARVIDAL 2/0AWG 7H | E15: CONECTOR COMP TER BIMETAL 2-1/0AWG 1AGUJ | G15: FUSIBLE LIMITADOR 18A 15,5KV CLASE C,CM5(TIPO NX) | H15: ABRAZADERA 5-5 1/2" 4 T | I15: INTERRUPTOR 4 VIAS AISLADO EN SF6 | K15: POSTE ACERO 11.28M 211KG LIVIANO | M15: CONDENS 1F INTEMP 60KVAR 4800V75KV BIL 60HZ | N15: SECCIONAD 3F TR/MAN 3V 15KV 600A SF6 FRAM6 | O15: CINTA AISLANT PLAST 3/4"X0007X66'NEGRO BT | P15: TDI 1F 13800/120-240V 50KVA | Q15: TRANSF. DE POTENCIA 23,9/13,8 KV 15 MVA | R15: BUSHING PARA TRANSFORMADOR DE POTENCIA DE 8MVA EN SALIDA DE 13,8 KV | U15: PINTURA MARINA ( EPOXICA )
A16: CONO ESFUERZO T/EXT 1P 15KV 250 MCM | C16: LAMPARA VAPOR SODIO 220V 400W E40 | D16: CONDUCTOR AMES ARVIDAL 2AWG 7H | E16: CONECTOR COMP TERM BIMETAL 350KCM 2AGUJ | G16: FUSIBLE LIMITADOR 30A 15,5KV CLASE C,CM5 (TIPO NX) | H16: ABRAZADERA 6-6 1/2" 3 T | I16: INTERRUPTOR EN VACÍO TIPO CANISTER | K16: POSTE ACERO 12.20M 282KG LIVIANO | M16: CONDENS 1F INTEMP 100KVAR 4800V75KV BIL 60HZ | O16: CINTA AISLANTE GOMA 3/4" ANCHO AT NEGRO | P16: TRF PED 3F 150KVA 13800-208Y/120V | Q16: TRANSF. DE POTENCIA 23,9/13,8 KV 10 MVA | R16: JUEGO DE EMPACADURA PARA CUBA DE TP DE 8MVA | U16: RED O MAYA Y BARRAS PARA PUESTA TIERRA
A17: AISLADOR DE ESPIGA PARA 34,5 KV | C17: CAJAS DE CONTROL DE A.P. 2X60 AMP. | D17: CONDUCTOR COBRE SEMIDURO 4AWG SOLIDO | E17: CONECTOR COMP CUÑA BIMET 4/0-250MCM CART | G17: FUSIBLE LIMITADOR 40A 15,5KV CLASE C,CM5 (TIPO NX) | H17: ABRAZADERA 6-6 1/2" 4 T | I17: INTERRUPTOR EN VACÍO TIPO MOLDEADO | K17: POSTE ACERO 12.20 M 437KG PESADO | M17: CONDENS 1F INTEMP 110KVAR 4800V75KV BIL 60HZ | O17: CINTA AISLANTE PLÁSTICO | P17: TDP 13800D/120-208V 300KVA | Q17: TRANSF. DE POTENCIA 23,9/13,8 KV 6,5 MVA | R17: TABLERO DE PROTECCIONES DEL TRANSFORMADOR N°2, 50 MTS DE CONDUCTOR DE CONTROL 7X12 | U17: SILICA GEL NARANJA GRANULADA BIODEGRADABLE
A18: AISLADOR PORCELANA BASE ANSI TR04 | C18: RELE CONTR ALUMBRADOPUBLICO2P240/480 V 6 | D18: CABLE TTU COBRE 1/0AWG 600V 19H 90°C | E18: CONECTOR T/COMP TERM 2A BIMETAL 2/0 | G18: FUSIBLE LIMITADOR 50A 15,5KV CLASE C,CM5 (TIPO NX) | H18: ABRAZADERA PARA TRANSFORMADOR DE 3-4" | I18: TRANSFERENCIA AUTOMÁTICA EN VACÍO C/PROT | K18: POSTE ACERO 13.72M 388KG PESADO | M18: CONDENS 1F INTEMP 115KVAR 4800V75KV BIL 60HZ | O18: CINTA CU-SN ESP:0.016" LONG:15' ANCHO:1" | P18: TDP 3F 23900Y/120-208V 150KVA RA | U18: SISTEMADEPUESTAATIERRA
A19: CUBO AG PARA AISLADOR BASE ANSI TR04 | C19: CAJA EQUIPO CONTROL ALUMBRADO PUBLICO | D19: CABLE TTU COBRE 2AWG 600V 7H 90°C | E19: CONECTOR CUÑA ESTRIBO C/C 4/0-2 | G19: FUSIBLE MOLDEADO 100 AMP 15KV | H19: ABRAZADERA PARA TRANSFORMADOR DE 4-6" | I19: TRANSFERENCIA AUTOMÁTICA TIPO RAD 12 KV | K19: POSTE ACERO 13.72M 250KG | M19: CONDENS 1F INTEMP 200KVAR 4800V75KV BIL 60HZ | O19: CINTA MALLA CU ESTAÑADO | P19: TDP 3F 23900Y/120-208V 225KVA RA | U19: CERRADURA
A20: AISLADOR PORCELAN ESPIGA ANSI 56-3 35 KV | C20: CONDENSADOR DE 20 M.F. 330 V, P/ LUMINAR | D20: CABLE TTU COBRE 4AWG 600V 7H 90°C | E20: CONECTOR COMP TERM BIMETAL 500MCM 2AGUJ | G20: FUSIBLE MOLDEADO 100 AMP 5KV | H20: ABRAZADERA UNIVERSAL AG 45", 4 TORN | I20: TRANSFERENCIA AUTOMÁTICA TIPO RAD 4.8 KV | K20: POSTE ACERO 8.23M 116KG LIVIANO | M20: CONDENS AT 1F INTEMP 50KVAR 7200V95KV BIL | O20: CINTA SEMICONDUCTORA 3/4" X 0030" X 15 | P20: TDP 3F 23900Y/120-208V 300KVA RA | U20: MANTO PARA IMPERMEABILIZAR
A21: AISLADOR PORCELAN PEDESTA ANSI 57-3 35KV | C21: CONDENSADOR 30UF 330V P/LUMIN. V/NA 250W | D21: CABLE TTU COBRE 6AWG 600V 7H 90°C | E21: CONECTOR TERMINAL COMPRESION CU 4 AWG BT | G21: FUSIBLE MOLDEADO 150 AMP 5KV | H21: ABRAZADERAS 4" A 4 1/2 | I21: BOBINA DE DISPARO Y CIERRE | K21: POSTE ACERO 8.23M 178KG PESADO | M21: CONDENS AT 1F INTEMP 60KVAR 7200V95KV BIL | O21: CINTAS DE COLOR PARA IDENTIFICAR | P21: TDP 3F 23900Y/120-208V 500KVA RA | U21: PUERTA DE 1,50*2,10
A22: AISLADOR PORCELANA CAMPANA ANTIFOG 24 KV | C22: CONDENSADOR P/LUMINARIA DE 40 UF | D22: CABLE TTU PE-PVC 250KCM 600V 37H 75°C | E22: GRAPA SENCILLA PARA GUAYA 3/8 | G22: FUSIBLE MOLDEADO 65 AMP 15KV | H22: ADAPTADOR A/G 128 X 112 CRUCETA 3-4 1/2 | I22: INTERRUPTOR POTENCIA VACIO 34,5 KV SF6 800A | K22: POSTE ACERO 9.14M 159KG LIVIANO | M22: CONDENS AT 1F INTEMP 100KVAR 7200V95KV BIL | O22: CINTAS SEMICONDUCTIVA | P22: TDP 3F 23900Y/120-208V 75KVA AN | U22: TRAPOS ESTERILIZADOS
A23: AISLADOR DE TRACCION PARA GUAYA DE ACERO | C23: CONTACTOR TRIPOLAR 120/240V 150A | D23: CABLE TTU PE-PVC 350KCM 600V 37H 75°C | E23: CONECT COMPRES DERIV AL-CU 1/0 A 1/0 AWG | G23: FUSIBLE MOLDEADO 80 AMP 15KV | H23: ADAPTADOR CRUCETA 5X4X13/4X0.1" D.11/16" | I23: CUCHILLAS DE 600A | K23: BRAZO DOBLE/LATIGO 1,80 MTS15°POSTE HEX | M23: CONDENS AT 1F INTEMP 110KVAR 7200V95KV BIL | O23: PROTECCION CONTRA ARCO Y FUEGO ANCHA | P23: TDP 3F 23900Y/120-208V 150KVA AN | Q23: TRANSF. DE POTENCIA 23,9/8 kV 15 MVA | U23: PINTURA VER MAR
A24: ADAPTADOR MODULAR CABLE 250MCM 15KV 600A | C24: CONTACTOR AP 3P 500V 110A BOBINA 120V | D24: CABLE TTU COBRE 4/0 AWG 600V 19H 75°C | E24: CONECTOR CU P/PUESTA A TIERRA NO. 2 AWG | G24: FUSIBLE TIPO H 15-27KV 3A | H24: ALAMBRE CU BLANDO SOLIDO NO.4 AWG | I24: TIPO CELDA CON INTERRUPTOR TENSION 15 KV Y 500 AMPERIOS | K24: BRAZO SIMPLE ACR T/LATIGO1,8M 15°P/HEXAG | M24: CONDENS AT 1F INTEMP 115KVAR 7200V95KV BIL | P24: TDP 3F 23900Y/120-208V 225KVA AN | Q24: TRANSF. DE POTENCIA 34,5/13,8 kV 10 MVA | U24: IMPULSOR DE DETONACION COLOR AZUL
A25: ADAPTADOR MODULAR CABLE 500kcmil15KV600A | C25: CONTACTOR TIPO AC-1, 160A, BOBINA 240V | D25: CABLE TTU COBRE 500KCM 600V 37H 75°C | E25: CONECTOR CU P/PUESTA A TIERRA NO. 6 AWG | G25: FUSIBLE TIPO K 15-27KV 10A | H25: AMARRE LATERAL PREFORMADO DOBLE PARA CONDUCTOR DE ALUMINIO 4/0 | I25: INTERRUPTOR DE POTENCIA 24KV 1250 AMP | K25: MANGUITO P/POSTE DISTRIBUCION Ø 11,43 CM | M25: CONDENS AT 1F INTEMP 200KVAR 7200V95KV | P25: TDP 3F 23900Y/120-208V 300KVA AN | Q25: TRANSF. DE POTENCIA 34,5/13,8 kV 20 MVA | U25: ELECTRODOS SOLDADURA
A26: ADAPTADOR MODULAR P/CABLE 2/0 15KV 600A | C26: BASE SOPORTE INTERRUP FOTOELEC 120-240V | D26: CONDUCTOR CU CONCENTRICO2X8+1X10AWG 600V | E26: CONECTOR TERMINAL 1/0 | G26: FUSIBLE TIPO K 15-27KV 12A | H26: AMARRE PREFORMADO 1/0 | I26: TIPO INTERPERIE DE 13,8 KV 400 AMP | K26: MANGUITO P/POSTE DISTRIBUCION Ø 17,78 CM | M26: CONDENSADOR EN DERIVACION DE 100 kVAr, 7,96 kV, 60 HZ; 38/125 kV BIL, CON RESISTENCIA INTERNA DE DESCARGA. | P26: TDP 3F 23900Y/120-208V 500KVA AN | Q26: TRANSF. DE POTENCIA 34,5/13,8 kV 25 MVA | U26: FULMINANTE
A27: ADAPTADOR PUESTA TIERRA 500KCM y 750KCM | C27: INTERRUPTOR FOTOELECTRICO NA 120V | D27: CABLE AL CUADRUPLEX 1/0AWG 3P MENS 600V | E27: CONECTOR TERMINAL 4/0 | G27: FUSIBLE TIPO K 15-27KV 15A | H27: AMARRE TMNAL PREF 1/0 AWG | K27: PERNO ANCLAJE GALV-1"X90CM POSTE AP | M27: CONDENSADOR EN DERIVACION DE 200 kVAr, 7,96 kV, 60 HZ; 38/125 kV BIL, CON RESISTENCIA INTERNA DE DESCARGA. | P27: TDP 3F 23900Y/120-208V 750KVA AN | Q27: TRANSF. DE POTENCIA 34,5/13,8 kV 30 MVA | U27: SOLVENTE DIELÉCTRICO
A28: ADAPTADOR PUESTA-TIERRA 2 Y 2/0 y 250KCM | C28: INTERRUPTOR FOTOELECTRICO NC 120-240V | D28: CABLE AL CUADRUPLEX 4/0AWG 3P MENS 600V | E28: CONECTOR AL COMP. TERMINAL 750 MCM | G28: FUSIBLE TIPO K 15-27KV 20A | H28: AMARRE TMNL PREFOR CBLE 1/0AWG L:66.04CM | K28: POSTE ACERO HEXAGONAL 11,20 MTS. A.P. | M28: CONDENSADOR EN DERIVACION DE 50 kVAr, 7,96 kV, 60 HZ; 38/125 kV BIL, CON RESISTENCIA INTERNA DE DESCARGA. | P28: TDI 1F 13800/120-240V 100KVA | Q28: TRANSF. DE POTENCIA 34,5/13,8 kV 40 MVA
A29: CODO N. 2/0 | C29: LUMINARIA VS 100W 120V CUTOFF GUIRNALDA | D29: CABLE AL CUADRUPLEX 4AWG 3P Y MENS 600V | E29: CONECTOR CU P/PUESTA TIERRA 3/8"EN POSTE | G29: FUSIBLE TIPO K 15-27KV 25A | H29: AMARRE TMNL PREFRM CBLE 4/0AWG L:86.36CM | K29: POSTE TUBULAR ACERO 14.10M 3SECC REFORZ | M29: CONDENSADOR MONOFÁSICO 50 KVAR, 13,8 KV/7,9KVln | P29: TDI 1F 13800/240-480V 250KVA | Q29: TRANSF. DE POTENCIA 30/12,47 kV 20 MVA
A30: DISPOSITIVO AISLANTE ACOPLAMTO 15KV 600A | C30: LUMINARIA PARA LAMPARA VAPOR NA 100 W | D30: CABLE AL TRIPLEX 1/0AWG 19H 2P/MENS 600V | E30: CONECTOR AL DERIV. COMP. 250 A 500 MCM | G30: FUSIBLE TIPO K 15-27KV 3A | H30: ANCLA EXPANSION 180X15,9X152MM 6X5/8" | K30: MANGUITO P/POSTE DISTRIBUCION Ø 16,83 CM ES | M30: CONDENSADOR MONOFÁSICO 100 KVAR, 13,8 KV/7,9KVln | P30: TDI 1F 13800/240-480V 333KVA | Q30: TRANSF. DE POTENCIA 30/12,47 kV 10 MVA
A31: MANGA MODULAR AISL D/EXTENSION 15KV 600A | C31: LUMINARIA DE NA 150 W 208/240 V | D31: CABLE AL TRIPLEX 4/0AWG 19H 2P/MENS 600V | E31: CONECTOR COMP. TUBULAR LARGO 1/0 X 1/0 | G31: FUSIBLE TIPO K 15-27KV 5A | H31: ANCLA EXPANSION 210X22MM 8X5/8" | K31: POSTE 12M REFORZADO | M31: CONDENSADOR MONOFÁSICO 200 KVAR, 13,8 KV/7,9KVln | P31: TDPOENEL 1F 13,8KV 120/240 75KVA | Q31: TRANSF. DE POTENCIA 34,5/13,8 kV 5 MVA
A32: RECEPTACULO MODULAR EN "T" 15KV 600A | C32: LUMINARIA VAPOR SODIO 208-240V 250W E40 | D32: CABLE AL TRIPLEX 4AWG 2P Y MENSAJERO600V | E32: CONECTOR COMP. TUBULAR CORTO 336,4 MCM | G32: FUSIBLE TIPO K 15-27KV 8A | H32: ANILLOS PARA TUB ROSCADO CONDUIT 4” | K32: BRAZO 13/4” X 1,5 MTS | P32: TDI 1F 13800/120-240V 15KVA | Q32: TRANSF. DE POTENCIA 34,5/13,8 KV - 2,5 MVA
A33: TERMINAL AISL P/RECEPTACULO "T" 15KV 600A | C33: LUMINARIA VAPOR SODIO 208/240V 400W E40 | D33: CABLE CU 2/0AWG 19H TR-XLPE-LLDPE 1P 15K | E33: CONECTOR COMP. TUBULAR LARGO 336,4 MCM | G33: FUSIBLE TIPO K 30 AMP | H33: ANILLOS PARA TUBOS PVC 4” | P33: TDI 1F 13800/120-240V 167,5KVA | Q33: TRANSF. DE POTENCIA 34,5/13,8 KV - 3 MVA
A34: DISPOSITIVO AISLANTE ACOPLAM | C34: ADAPTADOR DE PORCELANA DE SOCATE E27 A SOCATE E40 (AMPLIADOR) | D34: CABLE CU 250MCM 61H1P600VPLT-PVC A/FUEGO | E34: CONECTOR COMP.TERMINAL ALCU 336,4 MCM | G34: FUSIBLE TIPO K 40 AMP | H34: ARANDELA DE PRESION DE ACERO GALVANIZADO; Ø= 3/8” ;ESPESOR = 2.38 mm x 3.58 mm | P34: TRF SUM 3F 750KVA 4800X12470V-208Y/120V | Q34: TRANSF. DE POTENCIA 34,5/13,8KV 36 MVA
A35: RECEPTACULO MODULAR EN T | C35: LUMIN LED AP 68-102W EQ NA ALTPRES 150W | D35: CABLE CU 500MCM 37H TR-XLPE-LLDPE 1P 15K | E35: CONECTOR COMP. TUBULAR CORTO 1/0 X 1/0 | G35: FUSIBLE TIPO K 6 AMP | H35: ARANDELA DE PRESION DE ACERO GALVANIZADO; Ø= 5/8” ;ESPESOR = 3.96 mm x 5.15 mm | P35: TRF SUM 3F 1000KVA 4800X12470V-208Y/120V | Q35: TRANSF. DE POTENCIA 23,9/13,8 KV 6,5 MVA
A36: ADAPTADOR MODULAR CABLE # 2 MCM 15KV 600A | C36: LUMIN LED AP 129-194W EQ NA ALTPRES 250W | D36: CABLE CU DESNUDO 2/0AWG 19H TR BLANDO 1P | E36: CONECTOR CU PERMAGRIP CAL. 8 2/0 AWG | G36: FUSIBLE TIPO K 65 AMP | H36: ARANDELA PLANA 1/2" BRONCE SILICIO | P36: TRF PEDEST 3F 12470/7200-208/120 300KVA
A37: ADAPTADOR MODULAR CABLE #2KCMIL15KV600A | C37: LUMIN LED AP 219-330W EQ NA ALTPRES 400W | D37: CABLE CU DESNUDO 250KCM 37H TR BLANDO 1P | E37: CONECTOR TERMINAL BIMETALICO PLUG 1/0AWG | G37: FUSIBLE TIPO T 15-27KV 10A | H37: ARANDELA PRES:1/2"BRONC-SI ESP:317X434MM | P37: TRF PEDEST 3F 12470/7200-208/120 500KVA
A38: ADAPTADOR MODULAR CABLE 2/0 MCM 15KV 600A | C38: ARRANCADOR P/LUMIN SODIO A/P 250W 220V | D38: CABLE CU DESNUDO 2AWG 7H TR DURO 1P | E38: CONECTOR TERMINAL 500 | G38: FUSIBLE TIPO T 15-27KV 15A | H38: ASA FIJACION P/CODO ROMPECARGA 15KV 200A | P38: TRF PEDEST 3F 12470/7200-208/120 750KVA
A39: ADAPTADOR MODULAR CABLE 2/0KCMIL15KV600A | C39: FUSIBLE CART CAJA ALUMB PUBLICO 600V 60A | D39: CABLE CU DESNUDO 500KCM 37H TR BLANDO 1P | E39: CONECTOR TERMINAL 750 | G39: FUSIBLE TIPO T 15-27KV 20A | H39: ASIENTO 7.62X5.08X2.69 CM PERCHA | P39: TDI 1F 13800/120-240V 75KVA
A40: ADAPTADOR MODULAR CABLE 250 | C40: FOTOCELDA NC TIPO ENCHUFE 10 A 120/240V | D40: CABLE CU DESNUDO 6AWG, 7H TR DURO 1P | E40: CONECTOR AL DERIV.COMP. 2/0AWG A 1/0AWG | G40: FUSIBLE TIPO T 15-27KV 25A | H40: BARRA ACER COBRIZ 5/8" X 8"PUESTA-TIERRA | P40: TDI 1F 34500/120-240V 25KVA
...

Sheet PRECIOS
A1: DESCRIPCIÓN DEL MATERIAL | B1: UNIDAD DE MEDIDA | C1: PRECIOS UNITARIOS EUROS
A2: ABARAZADERA UNIVERSAL 6 A 6 3/4” X 3/8” | B2: JG | C2: 6.8
A3: ABRAZADERA 3 1X 3 1/2"X 3/4" | B3: JG | C3: 6.8
A4: ABRAZADERA 3-3 1/2" 3 T | B4: PZA | C4: 4.4625
A5: ABRAZADERA 3-3 1/2" 4 T | B5: PZA | C5: 5.1
A6: ABRAZADERA 4 -4 1/2" X 3/8"REFORZADO | B6: JG | C6: 6.8
A7: ABRAZADERA 4-4 1/2" 3 T | B7: PZA | C7: 4.8875
A8: ABRAZADERA 4-4 1/2" 4 T | B8: PZA | C8: 5.95
A9: ABRAZADERA 5-5 1/2" 3 T | B9: PZA | C9: 4.8
A10: ABRAZADERA 5-5 1/2" 4 T | B10: PZA | C10: 6.8
A11: ABRAZADERA 6-6 1/2" 3 T | B11: PZA | C11: 4.8
A12: ABRAZADERA 6-6 1/2" 4 T | B12: PZA | C12: 7.4375
A13: ABRAZADERA PARA TRANSFORMADOR DE 3-4" | B13: PZA | C13: 46.75
... A747: TRANSF. DE POTENCIA 34,5/13,8 kV 30 MVA | B747: UND | C747: 1260000
A748: TRANSF. DE POTENCIA 34,5/13,8 kV 40 MVA | B748: UND | C748: =42000*40 -> 1680000
A749: TRANSF. DE POTENCIA 30/12,47 kV 20 MVA | B749: UND | C749: =20*42000 -> 840000
A750: TRANSF. DE POTENCIA 30/12,47 kV 10 MVA | B750: UND | C750: =10*42000 -> 420000
A751: TRANSF. DE POTENCIA 34,5/13,8 kV 5 MVA | B751: UND | C751: 210000
A752: TRANSFERENCIA AUTOMÁTICA EN VACÍO C/PROT | B752: UND | C752: 64339.623
A753: TRANSFERENCIA AUTOMÁTICA TIPO RAD 12 KV | B753: UND | C753: 24528.302
A754: TRANSFERENCIA AUTOMÁTICA TIPO RAD 4.8 KV | B754: UND | C754: 24528.302
A755: TRANSF. DE POTENCIA 34,5/13,8 KV - 2,5 MVA | B755: UND | C755: 105000
A756: TRANSF. DE POTENCIA 34,5/13,8 KV - 3 MVA | B756: UND | C756: 126000
A757: TRANSF. DE POTENCIA 34,5/13,8KV 36 MVA | B757: UND | C757: =36*42000 -> 1512000 | D757: =+C757/36 -> 42000
A758: TRANSF. DE POTENCIA 23,9/13,8 KV 20 MVA | B758: UND | C758: =20*42000 -> 840000
A759: TRANSF. DE POTENCIA 23,9/13,8 KV 15 MVA | B759: UND | C759: =15*42000 -> 630000
A760: TRANSF. DE POTENCIA 23,9/13,8 KV 10 MVA | B760: UND | C760: =10*42000 -> 420000
A761: TRANSF. DE POTENCIA 23,9/13,8 KV 6,5 MVA | B761: UND | C761: 273000
A762: TRANSFORMADORES DE CORRIENTE | B762: UND | C762: 438.22
A763: TRANSFORMADORES DE TENSION | B763: UND | C763: 428.71323
A764: TRAPOS ESTERILIZADOS | B764: KG | C764: 3
A765: TRF INTEMP 1F 25KVA 4800X7200V-120/240V | B765: UND | C765: 1950
A766: TRF PED 3F 150KVA 13800-208Y/120V | B766: UND | C766: 13000
A767: TRF PEDEST 3F 12470/7200-208/120 300KVA | B767: UND | C767: 24000
A768: TRF PEDEST 3F 12470/7200-208/120 500KVA | B768: UND | C768: 34500
A769: TRF PEDEST 3F 12470/7200-208/120 750KVA | B769: UND | C769: 46000
A770: TRF SUM 1F 4800X7200V-120/240V 100KVA | B770: UND | C770: 9800
A771: TRF SUM 1F 4800X7200V-120/240V 167KVA | B771: UND | C771: 16000
A772: TRF SUM 1F 4800X7200V-120/240V 250KVA | B772: UND | C772: 22000
... A818: CONDENSADOR MONOFÁSICO 200 KVAR, 13,8 KV/7,9KVln | B818: UND | C818: 1228
...

Sheet Hoja2
A1: LINEAS DE MEDIA TENSION
A2: A 34,5 KV | B2: 22639.68 | C2: -----------
A3: A 13,8 KV | B3: 17121 | C3: 17121
A4: BATERÍAS ($/AH) (banco de baterías 500 A-H) | B4: 120.16 | C4: --------------
A5: RECTIFICADORES | B5: 29202.32 | C5: 29202.32
A6: TABLEROS DE PROTECCIÓN (Especificar el Equipo) | B6: -------------- | C6: --------------
A7: TABLERO TIPO PL 1 PROTECCION DE LINEA | B7: 133871.09 | C7: 133871.09
A8: TABLERO TIPO PL 3 PROTECCION DE LINEA | B8: 118309.38 | C8: 118309.38
A9: TABLERO TIPO TLP 3 TELEPROTECCION | B9: 84000.29 | C9: 84000.29
A10: TABLERO TIPO PB 1 PROTECCION DE BARRAS | B10: 136605.88 | C10: 136605.88
A11: TABLERO TIPO PB PROTECCION DE BARRAS Y FALLA INTERRUPTOR(6) | B11: 251665.96 | C11: 251665.96
A12: TABLERO TIPO TLP TELEPROTECCION(6) | B12: 92264.15 | C12: 92264.15
A13: TABLERO TIPO RF REGISTRADOR DE FALLAS(6) | B13: 92256.72 | C13: 92256.72
A14: TABLERO TIPO PT PROTECCION DE TRANSFORMADOR(6) | B14: 83169.77 | C14: 83169.77
A15: TABLERO TIPO PB PROTECCION DE BARRAS(6) | B15: 73166.44 | C15: 73166.44
A16: TABLERO TIPO PBF BREAKER FAILURE(6) | B16: 41336 | C16: 41336
A17: TABLERO TIPO TCOM1 COMUNICACIONES(6) | B17: 104659.97 | C17: 104659.97
A18: TABLERO TIPO TCOM2 COMUNICACIONES(6) | B18: 84000.29 | C18: 84000.29
... A24: TABLEROS 48 v.c.c. (6) | B24: 9507.98 | C24: 9507.98
A25: RELÉS PARA DIF TENS. (Especificar el Equipo) | B25: -------------- | C25: --------------
A26: Relé de línea ultrarrápido SEL-T401L (27) | B26: -------------- | C26: 19500
A27: Protección de línea de dominio del tiempo SEL-T400L(27) | B27: -------------- | C27: 15,600,00
A28: Sistema de protección, automatización y control SEL-421(27) | B28: -------------- | C28: 9370
A29: Sistema de protección de la transmisión SEL-311C(27) | B29: -------------- | C29: 6100
A30: Sistema de automatización y protección diferencial de corriente de línea SEL-311L(27) | B30: -------------- | C30: 7130
A31: Sistema de protección diferencial, automatización y control de línea avanzado SEL-411L(27) | B31: -------------- | C31: 11500
A32: Relé diferencial de corriente de línea SEL-387L(27) | B32: -------------- | C32: 3990
A33: Relé de protección de transformador SEL-487E(27) | B33: -------------- | C33: 9900
A34: Relé de protección de transformador SEL-787-2/-3/-4(27) | B34: -------------- | C34: 4000
A35: Relé de tensión y diferencial de corriente SEL-387E(27) | B35: -------------- | C35: 7810
A36: Sistema avanzado de protección del generador SEL-400G(27) | B36: -------------- | C36: 15600
A37: Relé diferencial de corriente y sobrecorriente SEL-387A(27) | B37: -------------- | C37: 4970
A38: Relé diferencial de alta impedancia SEL-587Z(27) | B38: -------------- | C38: 5330
A39: Relé diferencial de corriente SEL-587(27) | B39: -------------- | C39: 2820
... A46: Medidor de calidad de energía e ingresos SEL-735(27) | B46: -------------- | C46: 2150
A47: RECONECTADOR VACIO 34,5 KV 560A (14) | B47: 21000 | C47: 25650
A48: RECONECTADOR VACIO 13,8 KV560A(14) | B48: 18480 | C48: 20650
A49: RECONECTADOR DE POTENCIA 24 KV(14) | B49: 17355.9 | C49: 21588.43
A50: PRECIOS SECCIONADORES SUMERGIBLES REGION CAPITAL
A51: SECCIONADOR (3-fases, 15,5 kV, 600 A, 60 Hz- Short Time Currente, 25 kA/1s; Manual- SUMERGIBLE 4 vias, BARRA PARTIDA(24) | B51: 60757.75 | C51: -------------
...
