Workbook
Name __xlfn_IFERROR: #N/A
Name _3_RESUMEN_DE_CASOS_RECIBIDOS_Y_ATENDIDO: #REF!
Name ACTUALIZADO_25_08_2025: 'PRTSEN YARACUY (ACTUALIZADO)'!$A$73:$AG$73
Name AISLADORES_Y_COPAS: #REF!
Name ALCANCE_DEL_PROYECTO: 'PRTSEN YARACUY (ACTUALIZADO)'!$D$2:$D$73
Name ALUMBRADO_PUBLICO: #REF!
Name AÑO_DE_ATENCIÓN: 'PRTSEN YARACUY (ACTUALIZADO)'!$T$2:$T$73
Name CAPACIDAD__MVA__KM__MVAR: 'PRTSEN YARACUY (ACTUALIZADO)'!$O$2:$O$73
Name CATEGORIA: #REF!
Name DESCRIPCION_DEL_PROYECTO: 'PRTSEN YARACUY (ACTUALIZADO)'!$C$2:$C$73
Name DESEMBOLSO___2025: 'PRTSEN YARACUY (ACTUALIZADO)'!$W$2:$W$73
Name DESEMBOLSO___2026: 'PRTSEN YARACUY (ACTUALIZADO)'!$X$2:$X$73
Name DESEMBOLSO___2027: 'PRTSEN YARACUY (ACTUALIZADO)'!$Y$2:$Y$73
Name DESEMBOLSO___2028: 'PRTSEN YARACUY (ACTUALIZADO)'!$Z$2:$Z$73
Name DESEMBOLSO___2029: 'PRTSEN YARACUY (ACTUALIZADO)'!$AA$2:$AA$73
Name DESEMBOLSO___2030: 'PRTSEN YARACUY (ACTUALIZADO)'!$AB$2:$AB$73
Name DESEMBOLSO___2031: 'PRTSEN YARACUY (ACTUALIZADO)'!$AC$2:$AC$73
Name DIRECCION_DE_LA_INSTACION: 'PRTSEN YARACUY (ACTUALIZADO)'!$R$2:$R$73
Name ESTADO: 'PRTSEN YARACUY (ACTUALIZADO)'!$P$2:$P$73
Name ESTATUS_DEL_PROYECTO__EN_EJECUCION__POR_EJECUTAR__PARALIZADO__EJECUTADO: 'PRTSEN YARACUY (ACTUALIZADO)'!$J$2:$J$73
Name EXTCATEG_H: [1]EXTCATEG!$B$2:$B$30
Name FAMILIAS: #REF!
Name FASE_DEL_PROYECTO__CON_INGENIERIA__DETALLE__CON_IINGENIERIA_CONCEPTUAL__EN_PLANIFICACION: 'PRTSEN YARACUY (ACTUALIZADO)'!$I$2:$I$73
Name FECHA_ACTUALIZACION_DE_LOS_PROYECTOS: 'PRTSEN YARACUY (ACTUALIZADO)'!$AH$2:$AH$73
Name FECHA_DE_ATENCION: 'PRTSEN YARACUY (ACTUALIZADO)'!$S$2:$S$73
Name FECHA_FIN_DEL_PROYECTO: 'PRTSEN YARACUY (ACTUALIZADO)'!$V$2:$V$73
Name FECHA_INICIO_DEL_PROYECTO: 'PRTSEN YARACUY (ACTUALIZADO)'!$U$2:$U$73
Name FEDERAL: '[2]RESUMEN ESTADO'!$A$10:$A$35
Name IMPACTO_PARA_EL_SEN___BENEFICIOS: 'PRTSEN YARACUY (ACTUALIZADO)'!$F$2:$F$73
Name Ingenieria: [3]VAR!$A$2:$A$10
Name LAPSO_DE_EJECUCION_DEL_PROYECTO___EN_NRO_DE__MESES: 'PRTSEN YARACUY (ACTUALIZADO)'!$H$2:$H$73
Name MONTO_INVERSIÓN: 'PRTSEN YARACUY (ACTUALIZADO)'!$G$2:$G$73
Name MUNICIPIO: 'PRTSEN YARACUY (ACTUALIZADO)'!$Q$2:$Q$73
Name N°: 'PRTSEN YARACUY (ACTUALIZADO)'!$A$2:$A$73
Name NIVEL_DE_TENSION_DE_LA_INSTALACION: 'PRTSEN YARACUY (ACTUALIZADO)'!$M$2:$M$73
Name NIVELTENSION: [4]LISTA!$A$2:$A$10
Name NIVELTENSION: [5]LISTA!$A$2:$A$10
Name NOMBRE_DE_LA_INSTALACION: 'PRTSEN YARACUY (ACTUALIZADO)'!$L$2:$L$73
Name NOMBRE_DEL_PROYECTO: 'PRTSEN YARACUY (ACTUALIZADO)'!$B$2:$B$73
Name OBSERVACION1: 'PRTSEN YARACUY (ACTUALIZADO)'!$AF$2:$AF$73
Name OBSERVACION2: 'PRTSEN YARACUY (ACTUALIZADO)'!$AG$2:$AG$73
Name PRT_ESTADO_NNN: 'PRTSEN YARACUY (ACTUALIZADO)'!$AD$2:$AD$73
Name SITUACION_ACTUAL_DEL_PROYECTO: 'PRTSEN YARACUY (ACTUALIZADO)'!$E$2:$E$73
Name TIPO: 'PRTSEN YARACUY (ACTUALIZADO)'!$AE$2:$AE$73
Name TIPO_DE_INSTALACION: 'PRTSEN YARACUY (ACTUALIZADO)'!$K$2:$K$73
Name UNIDAD: #REF!
Name UNIDAD_DE_MEDIDA____MVA__MW__km: 'PRTSEN YARACUY (ACTUALIZADO)'!$N$2:$N$73

Sheet PRTSEN YARACUY (ACTUALIZADO)
A1: N° | B1: NOMBRE DEL PROYECTO | C1: DESCRIPCION DEL PROYECTO | D1: ALCANCE DEL PROYECTO | E1: SITUACION ACTUAL DEL PROYECTO | F1: IMPACTO PARA EL SEN (BENEFICIOS) | G1: MONTO INVERSIÓN | H1: LAPSO DE EJECUCION DEL PROYECTO ( EN NRO DE MESES) | I1: FASE DEL PROYECTO (CON INGENIERIA DETALLE, CON IINGENIERIA CONCEPTUAL, EN PLANIFICACION) | J1: ESTATUS DEL PROYECTO (EN EJECUCION, POR EJECUTAR, PARALIZADO, EJECUTADO) | K1: TIPO DE INSTALACION | L1: NOMBRE DE LA INSTALACION | M1: NIVEL DE TENSION DE LA INSTALACION | N1: UNIDAD DE MEDIDA ( MVA, MW, km) | O1: CAPACIDAD (MVA, KM, MVAR) | P1: ESTADO | Q1: MUNICIPIO | R1: DIRECCION DE LA INSTACION | S1: FECHA DE ATENCION | T1: AÑO DE ATENCIÓN | U1: FECHA INICIO DEL PROYECTO | V1: FECHA FIN DEL PROYECTO | W1: DESEMBOLSO $ 2025 | X1: DESEMBOLSO $ 2026 | Y1: DESEMBOLSO $ 2027 | Z1: DESEMBOLSO $ 2028 | AA1: DESEMBOLSO $ 2029 | AB1: DESEMBOLSO $ 2030 | AC1: DESEMBOLSO $ 2031 | AD1: PRT-ESTADO-NNN | AE1: TIPO | AF1: OBSERVACIONES | AG1: OBSERVACION2 | AH1: FECHA ACTUALIZACION DE LOS PROYECTOS
A2: 705 | B2: INSTALACIÓN DE 4 RECONECTADORES EN LA RED DE M.T S/E AROA 13.8 KV | C2: INSTALACIÓN DE 4 RECONECTADOR EN S/E AROA SALIDAS DE LOS CTOS: AROA, CARABOBO, CAYURE Y LAS CUMARAGUAS. | D2: PARA LA SALIDA (PÓRTICOS) DE LOS CTOS: AROA, CARABOBO, CAYURE Y LAS CUMARAGUAS. RECONECTADOR AUTOMÁTICO. TENSIÓN NOMINAL 15.6KV, CORRIENTE NOMINAL 650 AMP, CORRIENTE DE FALLA 40KA | E2: PENDIENTE | F2: LA INSTALACIÓN DE RECONECTADORES AUTOMÁTICOS EN REDES AÉREAS *PERMITE LA AUTOMATIZACIÓN Y MONITOREO DEL SISTEMA ELÉCTRICO, MEJORANDO LA DETECCIÓN Y RECUPERACIÓN ANTE FALLAS*. ESTO OPTIMIZA LA CONTINUIDAD DEL SERVICIO, REDUCE TIEMPOS DE INTERRUPCIÓN Y MINIMIZA EL IMPACTO DE EVENTOS TRANSITORIOS, GARANTIZANDO MAYOR ESTABILIDAD Y EFICIENCIA OPERATIVA EN LA RED | G2: 300000 | H2: 6 | I2: EN PLANIFICACION | J2: POR EJECUTAR | K2: CIRCUITO | L2: AROA | M2: 13,8 KV | N2: MVA | O2: 14 | P2: YARACUY | Q2: BOLÍVAR | R2: AROA | S2: 05/2026 | T2: 2026 | U2: 3/3/2026 | V2: 3/9/2026 | X2: 300000 | AD2: =+"PRT-"&P2&"-"&AI2 -> PRT-YARACUY-1 | AE2: CNO | AH2: ACTUALIZADO 25/08/2025 | AI2: 1
A3: 706 | B3: REHABILITACIÓN INTERRUPTOR DE LOS CTOS. EL GUAYABO Y MORCAPEL DE S/E CARBONERO | C3: INSTALACIÓN DE SISTEMAS DE INTERRUPTORES Y CONTROLES CELDAS EN MT 12,47 | D3: Instalación de interruptores y controles en celdas MT 12,47 kV, con integración a sistemas de monitoreo, optimizando la protección, maniobrabilidad y respuesta ante fallas en la red eléctrica. | E3: PENDIENTE | F3: La instalación de sistemas de interruptores y controles en celdas de MT 12,47 kV mejora la fiabilidad y seguridad del suministro eléctrico en el municipio Veroes, Yaracuy. Este tipo de infraestructura permite una mejor coordinación de protecciones, reduciendo fallas y tiempos de interrupción. Además, optimiza la distribución de energía, asegurando una operación más eficiente y estable para las comunidades beneficiadas. | G3: 351760 | H3: 6 | I3: EN PLANIFICACION | J3: POR EJECUTAR | K3: CIRCUITO | L3: CARBONERO | M3: 12.47 | N3: MVA | O3: 10 | P3: YARACUY | Q3: VEROES | R3: SAN FELIPE | S3: 05/2026 | T3: 2026 | U3: 3/3/2026 | V3: 3/9/2026 | X3: 351760 | AD3: =+"PRT-"&P3&"-"&AI3 -> PRT-YARACUY-2 | AE3: CNO | AH3: ACTUALIZADO 25/08/2025 | AI3: =+AI2+1 -> 2
A4: 707 | B4: INSTALACIÓN DE 1 RECONECTADORES EN LA RED DE M.T CTO. ZONA INDUSTRIAL SABANA DE PARRA, S/E SABANA DE PARRA 13.8 KV | C4: INSTALACIÓN DE 1 RECONECTADOR CTO. ZONA IND SABANA DE PARRA | D4: SUSTITUCIÓN DEL RECONECTADOR CTO. ZONA IND SABANA DE PARRA. INTERRUPTOR RECONECTADOR DAÑADO. LA CARGA ES TRANSFERIDA AL CTO. SABANA DE PARRA.. | E4: PENDIENTE | F4: LA INSTALACIÓN DE RECONECTADORES AUTOMÁTICOS EN REDES AÉREAS *PERMITE LA AUTOMATIZACIÓN Y MONITOREO DEL SISTEMA ELÉCTRICO, MEJORANDO LA DETECCIÓN Y RECUPERACIÓN ANTE FALLAS*. ESTO OPTIMIZA LA CONTINUIDAD DEL SERVICIO, REDUCE TIEMPOS DE INTERRUPCIÓN Y MINIMIZA EL IMPACTO DE EVENTOS TRANSITORIOS, GARANTIZANDO MAYOR ESTABILIDAD Y EFICIENCIA OPERATIVA EN LA RED | G4: 75000 | H4: 1 | I4: EN PLANIFICACION | J4: POR EJECUTAR | K4: CIRCUITO | L4: ZONA IND SABANA DE PARRA | M4: 13,8 KV | N4: MVA | O4: 4 | P4: YARACUY | Q4: JOSE ANTONIO PAÉZ | R4: S/E SABANA DE PARRA | S4: 03/2026 | T4: 2026 | U4: 3/3/2026 | V4: 3/4/2026 | X4: 75000 | AD4: =+"PRT-"&P4&"-"&AI4 -> PRT-YARACUY-3 | AE4: CNO | AH4: ACTUALIZADO 25/08/2025 | AI4: =+AI3+1 -> 3
A5: 708 | B5: ADECUACIÓN CAMBIO DE CALIBRE CTO. SAN PABLO | C5: CAMBIO DE CALIBRE CIRCUITO SAN PABLO EN 12,47 KV. S/E INDEPENDENCIA | D5: CAMBIO DE CALIBRE CIRCUITO SAN PABLO (SAN FELIPE D01) EN 12,47 KV DE APROXIMADO 4 KM POR OBSOLESCENCIA. S/E SAN FELIPE 2 | E5: PENDIENTE | F5: EL PROYECTO DE ADECUACIÓN DE LÍNEAS DE MEDIA TENSIÓN OPTIMIZA LA INFRAESTRUCTURA ELÉCTRICA MEDIANTE LA MODERNIZACIÓN DE CONDUCTORES, ESTRUCTURAS Y AISLADORES, MEJORANDO LA CAPACIDAD DE CARGA Y REDUCIENDO PÉRDIDAS POR EFECTO JOULE. SU IMPACTO SE TRADUCE EN *MAYOR EFICIENCIA ENERGÉTICA, REDUCCIÓN DE FALLAS Y AUMENTO DE LA CONFIABILIDAD DEL SISTEMA*, BENEFICIANDO TANTO A USUARIOS INDUSTRIALES COMO RESIDENCIALES, AL GARANTIZAR UNA DISTRIBUCIÓN ESTABLE Y SEGURA DE LA ENERGÍA. ADEMÁS, DISMINUYE COSTOS DE MANTENIMIENTO Y CONTRIBUYE A LA SOSTENIBILIDAD DEL SERVICIO ELÉCTRICO. | G5: 152930 | H5: 3 | I5: INGENIERIA CONCEPTUAL | J5: POR EJECUTAR | K5: CIRCUITO | L5: INDEPENDENCIA | M5: 12,47 KV | N5: KM | O5: 4 | P5: YARACUY | Q5: ARISTIDES BASTIDAS | R5: SAN FELIPE | S5: 11/2025 | T5: 2026 | X5: 152930 | AD5: =+"PRT-"&P5&"-"&AI5 -> PRT-YARACUY-4 | AE5: COP | AH5: ACTUALIZADO 25/08/2025 | AI5: =+AI4+1 -> 4
A6: 709 | B6: ADECUACIÓN CAMBIO DE CALIBRE CTO. CARABOBO | C6: CAMBIO DE CALIBRE CIRCUITO CARABOBO EN 13,8 KV. S/E AROA | D6: CAMBIO DE CALIBRE AL CIRCUITO CARABOBO EN NIVEL DE TENSIÓN 13,8 KV DE 4.85 KM. CONDUCTOR 2/0 AL DESDE LOS UREROS - LA VACA – BARLOVENTO. CAMBIO DE 10.5 KM A CALIBRE 2/0 AL DESDE SUBIDA A ARAKAL HASTA EL TIGRE. S/E AROA | E6: PENDIENTE | F6: EL PROYECTO DE ADECUACIÓN DE LÍNEAS DE MEDIA TENSIÓN OPTIMIZA LA INFRAESTRUCTURA ELÉCTRICA MEDIANTE LA MODERNIZACIÓN DE CONDUCTORES, ESTRUCTURAS Y AISLADORES, MEJORANDO LA CAPACIDAD DE CARGA Y REDUCIENDO PÉRDIDAS POR EFECTO JOULE. SU IMPACTO SE TRADUCE EN *MAYOR EFICIENCIA ENERGÉTICA, REDUCCIÓN DE FALLAS Y AUMENTO DE LA CONFIABILIDAD DEL SISTEMA*, BENEFICIANDO TANTO A USUARIOS INDUSTRIALES COMO RESIDENCIALES, AL GARANTIZAR UNA DISTRIBUCIÓN ESTABLE Y SEGURA DE LA ENERGÍA. ADEMÁS, DISMINUYE COSTOS DE MANTENIMIENTO Y CONTRIBUYE A LA SOSTENIBILIDAD DEL SERVICIO ELÉCTRICO. | G6: 185427.62 | H6: 2 | I6: INGENIERIA CONCEPTUAL | J6: POR EJECUTAR | K6: CIRCUITO | L6: AROA | M6: 13,8 KV | N6: KM | O6: 4.85 | P6: YARACUY | Q6: BOLÍVAR | R6: AROA | S6: 11/2025 | T6: 2026 | X6: 185427.62 | AD6: =+"PRT-"&P6&"-"&AI6 -> PRT-YARACUY-5 | AE6: COP | AH6: ACTUALIZADO 25/08/2025 | AI6: =+AI5+1 -> 5
A7: 710 | B7: ADECUACIÓN CAMBIO DE CALIBRE CTO HIGUERÓN | C7: CAMBIO DE CALIBRE CIRCUITO HIGUERÓN A 366 MCM. S/E INDEPENDENCIA | D7: CAMBIO DE CALIBRE CIRCUITO SAN FELIPE C02 EN 12,47 KV A CONDUCTOR 366 MCM. S/E SAN FELIPE 2. 3.5 KM. | E7: PENDIENTE | F7: EL PROYECTO DE ADECUACIÓN DE LÍNEAS DE MEDIA TENSIÓN OPTIMIZA LA INFRAESTRUCTURA ELÉCTRICA MEDIANTE LA MODERNIZACIÓN DE CONDUCTORES, ESTRUCTURAS Y AISLADORES, MEJORANDO LA CAPACIDAD DE CARGA Y REDUCIENDO PÉRDIDAS POR EFECTO JOULE. SU IMPACTO SE TRADUCE EN *MAYOR EFICIENCIA ENERGÉTICA, REDUCCIÓN DE FALLAS Y AUMENTO DE LA CONFIABILIDAD DEL SISTEMA*, BENEFICIANDO TANTO A USUARIOS INDUSTRIALES COMO RESIDENCIALES, AL GARANTIZAR UNA DISTRIBUCIÓN ESTABLE Y SEGURA DE LA ENERGÍA. ADEMÁS, DISMINUYE COSTOS DE MANTENIMIENTO Y CONTRIBUYE A LA SOSTENIBILIDAD DEL SERVICIO ELÉCTRICO. | G7: 133813.75 | H7: 3 | I7: INGENIERIA CONCEPTUAL | J7: POR EJECUTAR | K7: CIRCUITO | L7: INDEPENDENCIA | M7: 12,47 KV | N7: KM | O7: 3.5 | P7: YARACUY | Q7: SAN FELIPE | R7: SAN FELIPE | S7: 11/2025 | T7: 2026 | X7: 133813.75 | AD7: =+"PRT-"&P7&"-"&AI7 -> PRT-YARACUY-6 | AE7: COP | AH7: ACTUALIZADO 25/08/2025 | AI7: =+AI6+1 -> 6
A8: 711 | B8: ADECUACIÓN BT AROA, YUMARE Y PALMA SOLA | C8: MEJORAS EN SECTORES DE BT EN: AROA, YUMARE Y PALMA SOLA | D8: MEJORAS EN LA RED DE BT SECTORES: CASCO CENTRAL AROA, YUMARE CENTRO, PUEBLO NUEVO. | E8: PENDIENTE | F8: EL PROYECTO DE ADECUACIÓN DE LÍNEAS DE MEDIA TENSIÓN OPTIMIZA LA INFRAESTRUCTURA ELÉCTRICA MEDIANTE LA MODERNIZACIÓN DE CONDUCTORES, ESTRUCTURAS Y AISLADORES, MEJORANDO LA CAPACIDAD DE CARGA Y REDUCIENDO PÉRDIDAS POR EFECTO JOULE. SU IMPACTO SE TRADUCE EN *MAYOR EFICIENCIA ENERGÉTICA, REDUCCIÓN DE FALLAS Y AUMENTO DE LA CONFIABILIDAD DEL SISTEMA*, BENEFICIANDO TANTO A USUARIOS INDUSTRIALES COMO RESIDENCIALES, AL GARANTIZAR UNA DISTRIBUCIÓN ESTABLE Y SEGURA DE LA ENERGÍA. ADEMÁS, DISMINUYE COSTOS DE MANTENIMIENTO Y CONTRIBUYE A LA SOSTENIBILIDAD DEL SERVICIO ELÉCTRICO. | G8: 217912.31 | H8: 4 | I8: INGENIERIA CONCEPTUAL | J8: POR EJECUTAR | K8: CIRCUITO | L8: AROA, PALMA SOLA | M8: 120/240/208 | N8: KM | O8: 1.5 | P8: YARACUY | Q8: BOLIVAR, MANUEL MONGE Y VEROES (PUEBLO NUEVO) Y PALMA SOLA (FALCÓN) | R8: AROA | S8: 11/2025 | T8: 2026 | X8: 217912.31 | AD8: =+"PRT-"&P8&"-"&AI8 -> PRT-YARACUY-7 | AE8: COP | AH8: ACTUALIZADO 25/08/2025 | AI8: =+AI7+1 -> 7
A9: 712 | B9: ADECUACIÓN CAMBIO DE CALIBRE CTO . YRTG SUR Y NORTE | C9: CAMBIO DE CALIBRE CIRCUITOS YARITAGUA NORTE Y YARITAGUA SUR. S/E YARITAGUA | D9: CAMBIO DE CALIBRE EN CIRCUITOS YARITAGUA NORTE Y SUR (13,8 KV). CAMBIO DE AL 1/0 Y CU # 2 A 336 DE 0,693 KM TRAMO DESDE LA S/E YARITAGUA HASTA LA CALLE 21 CON CARRERA 8. | E9: PENDIENTE | F9: EL PROYECTO DE ADECUACIÓN DE LÍNEAS DE MEDIA TENSIÓN OPTIMIZA LA INFRAESTRUCTURA ELÉCTRICA MEDIANTE LA MODERNIZACIÓN DE CONDUCTORES, ESTRUCTURAS Y AISLADORES, MEJORANDO LA CAPACIDAD DE CARGA Y REDUCIENDO PÉRDIDAS POR EFECTO JOULE. SU IMPACTO SE TRADUCE EN *MAYOR EFICIENCIA ENERGÉTICA, REDUCCIÓN DE FALLAS Y AUMENTO DE LA CONFIABILIDAD DEL SISTEMA*, BENEFICIANDO TANTO A USUARIOS INDUSTRIALES COMO RESIDENCIALES, AL GARANTIZAR UNA DISTRIBUCIÓN ESTABLE Y SEGURA DE LA ENERGÍA. ADEMÁS, DISMINUYE COSTOS DE MANTENIMIENTO Y CONTRIBUYE A LA SOSTENIBILIDAD DEL SERVICIO ELÉCTRICO. | G9: 26495.123 | H9: 1 | I9: INGENIERIA CONCEPTUAL | J9: POR EJECUTAR | K9: CIRCUITO | L9: YARITAGUA SUR Y YARITAGUA NORTE | M9: 13,8 KV | N9: KM | O9: 0.693 | P9: YARACUY | Q9: PEÑA | R9: YARITAGUA | S9: 10/2025 | T9: 2026 | X9: 26495.123 | AD9: =+"PRT-"&P9&"-"&AI9 -> PRT-YARACUY-8 | AE9: COP | AH9: ACTUALIZADO 25/08/2025 | AI9: =+AI8+1 -> 8
A10: 713 | B10: ADECUACIÓN CAMBIO DE CALIBRE CTO. CENTRO | C10: CAMBIO DE CALIBRE CTO. CENTRO POR OBSOLESCENCIA. S/E INDEPENDENCIA | D10: CAMBIO DE CALIBRE EN CIRCUITO CENTRO (12,47 KV) EN TRAMO DE UN APROXIMADO DE 5 KM DE LINEA POR OBSOLESCENCIA. S/E SAN FELIPE 2 | E10: PENDIENTE | F10: EL PROYECTO DE ADECUACIÓN DE LÍNEAS DE MEDIA TENSIÓN OPTIMIZA LA INFRAESTRUCTURA ELÉCTRICA MEDIANTE LA MODERNIZACIÓN DE CONDUCTORES, ESTRUCTURAS Y AISLADORES, MEJORANDO LA CAPACIDAD DE CARGA Y REDUCIENDO PÉRDIDAS POR EFECTO JOULE. SU IMPACTO SE TRADUCE EN *MAYOR EFICIENCIA ENERGÉTICA, REDUCCIÓN DE FALLAS Y AUMENTO DE LA CONFIABILIDAD DEL SISTEMA*, BENEFICIANDO TANTO A USUARIOS INDUSTRIALES COMO RESIDENCIALES, AL GARANTIZAR UNA DISTRIBUCIÓN ESTABLE Y SEGURA DE LA ENERGÍA. ADEMÁS, DISMINUYE COSTOS DE MANTENIMIENTO Y CONTRIBUYE A LA SOSTENIBILIDAD DEL SERVICIO ELÉCTRICO. | G10: 191162.5 | H10: 4 | I10: INGENIERIA CONCEPTUAL | J10: POR EJECUTAR | K10: CIRCUITO | L10: INDEPENDENCIA | M10: 12,47 KV | N10: KM | O10: 5 | P10: YARACUY | Q10: SAN FELIPE | R10: SAN FELIPE | S10: 01/2026 | T10: 2026 | U10: 3/3/2026 | V10: 3/7/2026 | X10: 191162.5 | AD10: =+"PRT-"&P10&"-"&AI10 -> PRT-YARACUY-9 | AE10: COP | AH10: ACTUALIZADO 25/08/2025 | AI10: =+AI9+1 -> 9
A11: 714 | B11: ADECUACIÓN CAMBIO DE CALIBRE CTO. DUACA, MANZANITA Y CORPOVEN | C11: CAMBIO DE CALIBRE CIRCUITOS EN 13,8 KV DUACA, MANZANITA (TRAMO E/S-LAS CANARIAS), ZONA INDUSTRIAL, CORPOVEN. S/E YARITAGUA. | D11: CAMBIO DE CALIBRE CIRCUITOS EN 13,8 KV DUACA, MANZANITA (TRAMO E/S-LAS CANARIAS), ZONA INDUSTRIAL, CORPOVEN. S/E YARITAGUA. 4.5 KM | E11: PENDIENTE | F11: EL PROYECTO DE ADECUACIÓN DE LÍNEAS DE MEDIA TENSIÓN OPTIMIZA LA INFRAESTRUCTURA ELÉCTRICA MEDIANTE LA MODERNIZACIÓN DE CONDUCTORES, ESTRUCTURAS Y AISLADORES, MEJORANDO LA CAPACIDAD DE CARGA Y REDUCIENDO PÉRDIDAS POR EFECTO JOULE. SU IMPACTO SE TRADUCE EN *MAYOR EFICIENCIA ENERGÉTICA, REDUCCIÓN DE FALLAS Y AUMENTO DE LA CONFIABILIDAD DEL SISTEMA*, BENEFICIANDO TANTO A USUARIOS INDUSTRIALES COMO RESIDENCIALES, AL GARANTIZAR UNA DISTRIBUCIÓN ESTABLE Y SEGURA DE LA ENERGÍA. ADEMÁS, DISMINUYE COSTOS DE MANTENIMIENTO Y CONTRIBUYE A LA SOSTENIBILIDAD DEL SERVICIO ELÉCTRICO. | G11: 172046.25 | H11: 1 | I11: INGENIERIA CONCEPTUAL | J11: POR EJECUTAR | K11: CIRCUITO | L11: DUACA, MANZANITA Y CORPOVEN | M11: 13,8 KV | N11: KM | O11: 4.5 | P11: YARACUY | Q11: PEÑA | R11: YARITAGUA | S11: 01/2026 | T11: 2026 | U11: 3/3/2026 | V11: 3/4/2026 | X11: 172046.25 | AD11: =+"PRT-"&P11&"-"&AI11 -> PRT-YARACUY-10 | AE11: COP | AH11: ACTUALIZADO 25/08/2025 | AI11: =+AI10+1 -> 10
A12: 715 | B12: ADECUACIÓN CAMBIO DE CALIBRE CTO. LAS CUMARAGUAS | C12: CAMBIO DE CALIBRE CIRCUITO LAS CUMARAGUAS. S/E AROA | D12: CAMBIO DE CALIBRE CIRCUITO LAS CUMARAGUAS 13,8 KV DE 12 KM. CONDUCTOR 4/0 AL DESDE MINAS DE AROA HASTA SECTOR MILLA. S/E AROA | E12: PENDIENTE | F12: EL PROYECTO DE ADECUACIÓN DE LÍNEAS DE MEDIA TENSIÓN OPTIMIZA LA INFRAESTRUCTURA ELÉCTRICA MEDIANTE LA MODERNIZACIÓN DE CONDUCTORES, ESTRUCTURAS Y AISLADORES, MEJORANDO LA CAPACIDAD DE CARGA Y REDUCIENDO PÉRDIDAS POR EFECTO JOULE. SU IMPACTO SE TRADUCE EN *MAYOR EFICIENCIA ENERGÉTICA, REDUCCIÓN DE FALLAS Y AUMENTO DE LA CONFIABILIDAD DEL SISTEMA*, BENEFICIANDO TANTO A USUARIOS INDUSTRIALES COMO RESIDENCIALES, AL GARANTIZAR UNA DISTRIBUCIÓN ESTABLE Y SEGURA DE LA ENERGÍA. ADEMÁS, DISMINUYE COSTOS DE MANTENIMIENTO Y CONTRIBUYE A LA SOSTENIBILIDAD DEL SERVICIO ELÉCTRICO. | G12: 458790 | H12: 5 | I12: INGENIERIA CONCEPTUAL | J12: POR EJECUTAR | K12: CIRCUITO | L12: AROA | M12: 13,8 KV | N12: KM | O12: 12 | P12: YARACUY | Q12: BOLÍVAR | R12: AROA | S12: 05/2026 | T12: 2026 | U12: 3/3/2026 | V12: 3/8/2026 | X12: 458790 | AD12: =+"PRT-"&P12&"-"&AI12 -> PRT-YARACUY-11 | AE12: COP | AH12: ACTUALIZADO 25/08/2025 | AI12: =+AI11+1 -> 11
A13: 716 | B13: ADECUACIÓN CAMBIO DE CALIBRE CTO. COCOROTE | C13: CAMBIO DE CALIBRE 4/0 A 366 Y EXTENSIÓN CIRCUITO COCOROTE. S/E INDEPENDENCIA | D13: CAMBIO DE CALIBRE Y EXTENSIÓN CIRCUITO COCOROTE CONDUCTOR AL 4/0 A 366 MCM. S/E INDEPENDENCIA. 7,5 KM | E13: PENDIENTE | F13: EL PROYECTO DE ADECUACIÓN DE LÍNEAS DE MEDIA TENSIÓN OPTIMIZA LA INFRAESTRUCTURA ELÉCTRICA MEDIANTE LA MODERNIZACIÓN DE CONDUCTORES, ESTRUCTURAS Y AISLADORES, MEJORANDO LA CAPACIDAD DE CARGA Y REDUCIENDO PÉRDIDAS POR EFECTO JOULE. SU IMPACTO SE TRADUCE EN *MAYOR EFICIENCIA ENERGÉTICA, REDUCCIÓN DE FALLAS Y AUMENTO DE LA CONFIABILIDAD DEL SISTEMA*, BENEFICIANDO TANTO A USUARIOS INDUSTRIALES COMO RESIDENCIALES, AL GARANTIZAR UNA DISTRIBUCIÓN ESTABLE Y SEGURA DE LA ENERGÍA. ADEMÁS, DISMINUYE COSTOS DE MANTENIMIENTO Y CONTRIBUYE A LA SOSTENIBILIDAD DEL SERVICIO ELÉCTRICO. | G13: 286743.75 | H13: 4 | I13: INGENIERIA CONCEPTUAL | J13: POR EJECUTAR | K13: CIRCUITO | L13: INDEPENDENCIA | M13: 12,47 KV | N13: KM | O13: 7.5 | P13: YARACUY | Q13: COCOROTE | R13: SAN FELIPE | S13: 03/2026 | T13: 2026 | U13: 3/3/2026 | V13: 3/7/2026 | X13: 286743.75 | AD13: =+"PRT-"&P13&"-"&AI13 -> PRT-YARACUY-12 | AE13: COP | AH13: ACTUALIZADO 25/08/2025 | AI13: =+AI12+1 -> 12
A14: 717 | B14: ADECUACIÓN CAMBIO DE CALIBRE CTO. ARACOI | C14: CAMBIO DE CALIBRE 4/0 A 366 Y EXTENSIÓN CTO. ARACOI, S/E INDEPENDENCIA | D14: CAMBIO DE CALIBRE Y EXTENSIÓN CIRCUITO ARACAOI CONDUCTOR AL 4/0 A 366 MCM. S/E INDEPENDENCIA, | E14: PENDIENTE | F14: EL PROYECTO DE ADECUACIÓN DE LÍNEAS DE MEDIA TENSIÓN OPTIMIZA LA INFRAESTRUCTURA ELÉCTRICA MEDIANTE LA MODERNIZACIÓN DE CONDUCTORES, ESTRUCTURAS Y AISLADORES, MEJORANDO LA CAPACIDAD DE CARGA Y REDUCIENDO PÉRDIDAS POR EFECTO JOULE. SU IMPACTO SE TRADUCE EN *MAYOR EFICIENCIA ENERGÉTICA, REDUCCIÓN DE FALLAS Y AUMENTO DE LA CONFIABILIDAD DEL SISTEMA*, BENEFICIANDO TANTO A USUARIOS INDUSTRIALES COMO RESIDENCIALES, AL GARANTIZAR UNA DISTRIBUCIÓN ESTABLE Y SEGURA DE LA ENERGÍA. ADEMÁS, DISMINUYE COSTOS DE MANTENIMIENTO Y CONTRIBUYE A LA SOSTENIBILIDAD DEL SERVICIO ELÉCTRICO. | G14: 286743.75 | H14: 2 | I14: INGENIERIA CONCEPTUAL | J14: POR EJECUTAR | K14: CIRCUITO | L14: INDEPENDENCIA | M14: 12,47 KV | N14: KM | O14: 5.5 | P14: YARACUY | Q14: SAN FELIPE, INDEPENDENCIA | R14: SAN FELIPE | S14: 04/2026 | T14: 2026 | U14: 3/3/2026 | V14: 3/5/2026 | X14: 286743.75 | AD14: =+"PRT-"&P14&"-"&AI14 -> PRT-YARACUY-13 | AE14: COP | AH14: ACTUALIZADO 25/08/2025 | AI14: =+AI13+1 -> 13
A15: 718 | B15: ADECUACIÓN CAMBIO DE CALIBRE CTO. SAN RAFAEL | C15: CAMBIO DE CALIBRE 4/0 A 366 Y EXTENSIÓN CTO. SAN RAFAEL. S/E INDEPENDENCIA | D15: CAMBIO DE CALIBRE Y EXTENSIÓN CIRCUITO SAN RAFAEL CONDUCTOR AL 4/0 A 366 MCM. S/E INDEPENDENCIA. | E15: PENDIENTE | F15: EL PROYECTO DE ADECUACIÓN DE LÍNEAS DE MEDIA TENSIÓN OPTIMIZA LA INFRAESTRUCTURA ELÉCTRICA MEDIANTE LA MODERNIZACIÓN DE CONDUCTORES, ESTRUCTURAS Y AISLADORES, MEJORANDO LA CAPACIDAD DE CARGA Y REDUCIENDO PÉRDIDAS POR EFECTO JOULE. SU IMPACTO SE TRADUCE EN *MAYOR EFICIENCIA ENERGÉTICA, REDUCCIÓN DE FALLAS Y AUMENTO DE LA CONFIABILIDAD DEL SISTEMA*, BENEFICIANDO TANTO A USUARIOS INDUSTRIALES COMO RESIDENCIALES, AL GARANTIZAR UNA DISTRIBUCIÓN ESTABLE Y SEGURA DE LA ENERGÍA. ADEMÁS, DISMINUYE COSTOS DE MANTENIMIENTO Y CONTRIBUYE A LA SOSTENIBILIDAD DEL SERVICIO ELÉCTRICO. | G15: 286743.75 | H15: 2 | I15: INGENIERIA CONCEPTUAL | J15: POR EJECUTAR | K15: CIRCUITO | L15: INDEPENDENCIA | M15: 12,47 KV | N15: KM | O15: 4.5 | P15: YARACUY | Q15: SAN FELIPE, INDEPENDENCIA | R15: SAN FELIPE | S15: 06/2026 | T15: 2026 | U15: 3/3/2026 | V15: 3/5/2026 | X15: 286743.75 | AD15: =+"PRT-"&P15&"-"&AI15 -> PRT-YARACUY-14 | AE15: COP | AH15: ACTUALIZADO 25/08/2025 | AI15: =+AI14+1 -> 14
A16: 719 | B16: ADECUACIÓN CAMBIO DE CALIBRE CTO. YUMARE EXPRESS | C16: CAMBIO DE CALIBRE A 4/0 AL Y REUBICACIÓN CIRCUITO YUMARE EXPRESO. S/E PALMASOLA | D16: CAMBIO DE CALIBRE Y REUBICACIÓN CIRCUITO YUMARE EXPRESO 13,8 KV DE 7 KM DE CONDUCTOR Y HERRAJE DESDE EL CASERÍO LA CERO HASTA EL CASERÍO LA 13 INTERCONEXIÓN CIRCUITO YUMARE EXPRESO CON CIRCUITO CARABOBO (AL 4/0) Y CAMBIO 5 KM TRAMO TO5 – KM 41. S/E PALMASOLA | E16: PENDIENTE | F16: EL PROYECTO DE ADECUACIÓN DE LÍNEAS DE MEDIA TENSIÓN OPTIMIZA LA INFRAESTRUCTURA ELÉCTRICA MEDIANTE LA MODERNIZACIÓN DE CONDUCTORES, ESTRUCTURAS Y AISLADORES, MEJORANDO LA CAPACIDAD DE CARGA Y REDUCIENDO PÉRDIDAS POR EFECTO JOULE. SU IMPACTO SE TRADUCE EN *MAYOR EFICIENCIA ENERGÉTICA, REDUCCIÓN DE FALLAS Y AUMENTO DE LA CONFIABILIDAD DEL SISTEMA*, BENEFICIANDO TANTO A USUARIOS INDUSTRIALES COMO RESIDENCIALES, AL GARANTIZAR UNA DISTRIBUCIÓN ESTABLE Y SEGURA DE LA ENERGÍA. ADEMÁS, DISMINUYE COSTOS DE MANTENIMIENTO Y CONTRIBUYE A LA SOSTENIBILIDAD DEL SERVICIO ELÉCTRICO. | G16: 286743.75 | H16: 2 | I16: INGENIERIA CONCEPTUAL | J16: POR EJECUTAR | K16: CIRCUITO | L16: PALMA SOLA | M16: 13,8 KV | N16: KM | O16: 7 | P16: YARACUY | Q16: MANUEL MONGE | R16: YUMARE | S16: 07/2026 | T16: 2026 | U16: 3/3/2026 | V16: 3/5/2026 | X16: 286743.75 | AD16: =+"PRT-"&P16&"-"&AI16 -> PRT-YARACUY-15 | AE16: COP | AH16: ACTUALIZADO 25/08/2025 | AI16: =+AI15+1 -> 15
A17: 720 | B17: ADECUACIÓN CAMBIO DE CALIBRE CTO. CAMPO ELÍAS | C17: CAMBIO DE CALIBRE CIRCUITO CAMPO ELÍAS. S/E CHIVACOA | D17: CAMBIO DE CALIBRE CIRCUITO CAMPO ELÍAS EN 13,8 KV A CONDUCTOR 336 MCM. S/E CHIVACOA. 5,5 KM | E17: PENDIENTE | F17: EL PROYECTO DE ADECUACIÓN DE LÍNEAS DE MEDIA TENSIÓN OPTIMIZA LA INFRAESTRUCTURA ELÉCTRICA MEDIANTE LA MODERNIZACIÓN DE CONDUCTORES, ESTRUCTURAS Y AISLADORES, MEJORANDO LA CAPACIDAD DE CARGA Y REDUCIENDO PÉRDIDAS POR EFECTO JOULE. SU IMPACTO SE TRADUCE EN *MAYOR EFICIENCIA ENERGÉTICA, REDUCCIÓN DE FALLAS Y AUMENTO DE LA CONFIABILIDAD DEL SISTEMA*, BENEFICIANDO TANTO A USUARIOS INDUSTRIALES COMO RESIDENCIALES, AL GARANTIZAR UNA DISTRIBUCIÓN ESTABLE Y SEGURA DE LA ENERGÍA. ADEMÁS, DISMINUYE COSTOS DE MANTENIMIENTO Y CONTRIBUYE A LA SOSTENIBILIDAD DEL SERVICIO ELÉCTRICO. | G17: 286743.75 | H17: 2 | I17: INGENIERIA CONCEPTUAL | J17: POR EJECUTAR | K17: CIRCUITO | L17: CHIVACOA | M17: 13,8 KV | N17: KM | O17: 5.5 | P17: YARACUY | Q17: BRUZUAL | R17: CHIVACOA | S17: 05/2026 | T17: 2026 | U17: 3/3/2026 | V17: 3/5/2026 | X17: 286743.75 | AD17: =+"PRT-"&P17&"-"&AI17 -> PRT-YARACUY-16 | AE17: COP | AH17: ACTUALIZADO 25/08/2025 | AI17: =+AI16+1 -> 16
A18: 721 | B18: ADECUACIÓN CAMBIO DE CALIBRE CTO. PANAMERICANA | C18: CAMBIO DE CALIBRE CIRCUITO PANAMERICANA. S/E CHIVACOA | D18: CAMBIO DE CALIBRE CIRCUITO PANAMERICANA EN 13,8 KV A CONDUCTOR AL 4/0. S/E CHIVACOA. 3.5 KM. | E18: PENDIENTE | F18: EL PROYECTO DE ADECUACIÓN DE LÍNEAS DE MEDIA TENSIÓN OPTIMIZA LA INFRAESTRUCTURA ELÉCTRICA MEDIANTE LA MODERNIZACIÓN DE CONDUCTORES, ESTRUCTURAS Y AISLADORES, MEJORANDO LA CAPACIDAD DE CARGA Y REDUCIENDO PÉRDIDAS POR EFECTO JOULE. SU IMPACTO SE TRADUCE EN *MAYOR EFICIENCIA ENERGÉTICA, REDUCCIÓN DE FALLAS Y AUMENTO DE LA CONFIABILIDAD DEL SISTEMA*, BENEFICIANDO TANTO A USUARIOS INDUSTRIALES COMO RESIDENCIALES, AL GARANTIZAR UNA DISTRIBUCIÓN ESTABLE Y SEGURA DE LA ENERGÍA. ADEMÁS, DISMINUYE COSTOS DE MANTENIMIENTO Y CONTRIBUYE A LA SOSTENIBILIDAD DEL SERVICIO ELÉCTRICO. | G18: 286743.75 | H18: 2 | I18: INGENIERIA CONCEPTUAL | J18: POR EJECUTAR | K18: CIRCUITO | L18: CHIVACOA | M18: 13,8 KV | N18: KM | O18: 3.5 | P18: YARACUY | Q18: BRUZUAL | R18: CHIVACOA | S18: 09/2026 | T18: 2026 | U18: 3/3/2026 | V18: 3/5/2026 | X18: 286743.75 | AD18: =+"PRT-"&P18&"-"&AI18 -> PRT-YARACUY-17 | AE18: COP | AH18: ACTUALIZADO 25/08/2025 | AI18: =+AI17+1 -> 17
A19: 722 | B19: ADECUACIÓN CAMBIO DE CALIBRE CTO. MANZANITA | C19: ADECUACIÓN: CAMBIO DE CALIBRE A 336 MCM DEL CIRCUITO MANZANITA EN 13,8 KV. S/E YARITAGUA | D19: ADECUACIÓN: CAMBIO DE CALIBRE A 336 MCM DEL CIRCUITO MANZANITA EN 13,8 KV TRAMOS EL MOLINO- MANZANITA. S/E YARITAGUA. 4,5 KM | E19: PENDIENTE | F19: EL PROYECTO DE ADECUACIÓN DE LÍNEAS DE MEDIA TENSIÓN OPTIMIZA LA INFRAESTRUCTURA ELÉCTRICA MEDIANTE LA MODERNIZACIÓN DE CONDUCTORES, ESTRUCTURAS Y AISLADORES, MEJORANDO LA CAPACIDAD DE CARGA Y REDUCIENDO PÉRDIDAS POR EFECTO JOULE. SU IMPACTO SE TRADUCE EN *MAYOR EFICIENCIA ENERGÉTICA, REDUCCIÓN DE FALLAS Y AUMENTO DE LA CONFIABILIDAD DEL SISTEMA*, BENEFICIANDO TANTO A USUARIOS INDUSTRIALES COMO RESIDENCIALES, AL GARANTIZAR UNA DISTRIBUCIÓN ESTABLE Y SEGURA DE LA ENERGÍA. ADEMÁS, DISMINUYE COSTOS DE MANTENIMIENTO Y CONTRIBUYE A LA SOSTENIBILIDAD DEL SERVICIO ELÉCTRICO. | G19: 286743.75 | H19: 2 | I19: INGENIERIA CONCEPTUAL | J19: POR EJECUTAR | K19: CIRCUITO | L19: YARITAGUA | M19: 13,8 KV | N19: KM | O19: 4.5 | P19: YARACUY | Q19: SIMÓN PLANAS | R19: YARITAGUA | S19: 10/2026 | T19: 2026 | U19: 3/3/2026 | V19: 3/5/2026 | X19: 286743.75 | AD19: =+"PRT-"&P19&"-"&AI19 -> PRT-YARACUY-18 | AE19: COP | AH19: ACTUALIZADO 25/08/2025 | AI19: =+AI18+1 -> 18
A20: 723 | B20: ADECUACIÓN CTO. SALIDAS 34,5 S/E CHIVACOA | C20: SUMINISTRO DE EQUIPOS, ADECUACIÓN DE SALIDA 34,5 KV EN S/E CHIVACOA. INCLUYE SUMINISTRO E INSTALACIÓN DE INTERRUPTOR DE POTENCIA Y EQUIPO DE MEDICIÓN, MANDO Y CONTROL | D20: SUMINISTRO DE EQUIPOS, ADECUACIÓN DE SALIDA 34,5 KV EN S/E CHIVACOA. INCLUYE SUMINISTRO E INSTALACIÓN DE INTERRUPTOR DE POTENCIA Y EQUIPO DE MEDICIÓN, MANDO Y CONTROL | E20: PENDIENTE | F20: EL PROYECTO DE ADECUACIÓN DE LÍNEAS DE MEDIA TENSIÓN OPTIMIZA LA INFRAESTRUCTURA ELÉCTRICA MEDIANTE LA MODERNIZACIÓN DE CONDUCTORES, ESTRUCTURAS Y AISLADORES, MEJORANDO LA CAPACIDAD DE CARGA Y REDUCIENDO PÉRDIDAS POR EFECTO JOULE. SU IMPACTO SE TRADUCE EN *MAYOR EFICIENCIA ENERGÉTICA, REDUCCIÓN DE FALLAS Y AUMENTO DE LA CONFIABILIDAD DEL SISTEMA*, BENEFICIANDO TANTO A USUARIOS INDUSTRIALES COMO RESIDENCIALES, AL GARANTIZAR UNA DISTRIBUCIÓN ESTABLE Y SEGURA DE LA ENERGÍA. ADEMÁS, DISMINUYE COSTOS DE MANTENIMIENTO Y CONTRIBUYE A LA SOSTENIBILIDAD DEL SERVICIO ELÉCTRICO. | G20: 286743.75 | H20: 5 | I20: INGENIERIA CONCEPTUAL | J20: POR EJECUTAR | K20: CIRCUITO | L20: CHIVACOA | M20: 34,5 KV | N20: MVA | O20: 15 | P20: YARACUY | Q20: BRUZUAL | R20: CHIVACOA | S20: 07/2026 | T20: 2026 | U20: 3/3/2026 | V20: 3/8/2026 | X20: 286743.75 | AD20: =+"PRT-"&P20&"-"&AI20 -> PRT-YARACUY-19 | AE20: COP | AH20: ACTUALIZADO 25/08/2025 | AI20: =+AI19+1 -> 19
A21: 724 | B21: ADECUACIÓN CAMBIO DE CALIBRE CTO. EL PALMAR | C21: CAMBIO DE CALIBRE Y REUBICACIÓN CIRCUITO EL PALMAR. S/E YARITAGUA | D21: CAMBIO DE CALIBRE DE CONDUCTOR A 4/0 Y REUBICACIÓN DE CIRCUITO EL PALMAR EN 13.8 KV TRAMO DESDE LOS INVERNADEROS HASTA LA RECTA DE ARENALES. S/E YARITAGUA | E21: PENDIENTE | F21: EL PROYECTO DE ADECUACIÓN DE LÍNEAS DE MEDIA TENSIÓN OPTIMIZA LA INFRAESTRUCTURA ELÉCTRICA MEDIANTE LA MODERNIZACIÓN DE CONDUCTORES, ESTRUCTURAS Y AISLADORES, MEJORANDO LA CAPACIDAD DE CARGA Y REDUCIENDO PÉRDIDAS POR EFECTO JOULE. SU IMPACTO SE TRADUCE EN *MAYOR EFICIENCIA ENERGÉTICA, REDUCCIÓN DE FALLAS Y AUMENTO DE LA CONFIABILIDAD DEL SISTEMA*, BENEFICIANDO TANTO A USUARIOS INDUSTRIALES COMO RESIDENCIALES, AL GARANTIZAR UNA DISTRIBUCIÓN ESTABLE Y SEGURA DE LA ENERGÍA. ADEMÁS, DISMINUYE COSTOS DE MANTENIMIENTO Y CONTRIBUYE A LA SOSTENIBILIDAD DEL SERVICIO ELÉCTRICO. | G21: 217925.25 | H21: 2 | I21: INGENIERIA CONCEPTUAL | J21: POR EJECUTAR | K21: CIRCUITO | L21: YARITAGUA | M21: 13,8 KV | N21: KM | O21: 5.7 | P21: YARACUY | Q21: PEÑA | R21: YARITAGUA | S21: 05/2027 | T21: 2027 | U21: 3/3/2027 | V21: 3/5/2027 | Y21: 217925.25 | AD21: =+"PRT-"&P21&"-"&AI21 -> PRT-YARACUY-20 | AE21: COP | AH21: ACTUALIZADO 25/08/2025 | AI21: =+AI20+1 -> 20
A22: 725 | B22: ADECUACIÓN CAMBIO DE CALIBRE CTO. YUMARE EXPRESS - YUMARITO | C22: CAMBIO DE CALIBRE A 2/0 AL Y REUBICACIÓN CIRCUITO YUMARE EXPRESO. S/E PALMASOLA | D22: CAMBIO DE CALIBRE Y REUBICACIÓN CIRCUITO YUMARE EXPRESO 13,8 KV CONDUCTOR DE CU # 4, AL 2, AL 1/0 POR AL 2/0 Y HERRAJE DE 8 KM EN CEMENTERIO YUMARITO ARRANQUE DERIVACIÓN LA 13 SOCREMO. S/E PALMASOLA | E22: PENDIENTE | F22: EL PROYECTO DE ADECUACIÓN DE LÍNEAS DE MEDIA TENSIÓN OPTIMIZA LA INFRAESTRUCTURA ELÉCTRICA MEDIANTE LA MODERNIZACIÓN DE CONDUCTORES, ESTRUCTURAS Y AISLADORES, MEJORANDO LA CAPACIDAD DE CARGA Y REDUCIENDO PÉRDIDAS POR EFECTO JOULE. SU IMPACTO SE TRADUCE EN *MAYOR EFICIENCIA ENERGÉTICA, REDUCCIÓN DE FALLAS Y AUMENTO DE LA CONFIABILIDAD DEL SISTEMA*, BENEFICIANDO TANTO A USUARIOS INDUSTRIALES COMO RESIDENCIALES, AL GARANTIZAR UNA DISTRIBUCIÓN ESTABLE Y SEGURA DE LA ENERGÍA. ADEMÁS, DISMINUYE COSTOS DE MANTENIMIENTO Y CONTRIBUYE A LA SOSTENIBILIDAD DEL SERVICIO ELÉCTRICO. | G22: 305860 | H22: 5 | I22: INGENIERIA CONCEPTUAL | J22: POR EJECUTAR | K22: CIRCUITO | L22: PALMA SOLA | M22: 13,8 KV | N22: KM | O22: 8 | P22: YARACUY | Q22: MANUEL MONGE | R22: YUMARE | S22: 04/2026 | T22: 2026 | U22: 3/3/2026 | V22: 3/8/2026 | X22: 305860 | AD22: =+"PRT-"&P22&"-"&AI22 -> PRT-YARACUY-21 | AE22: COP | AH22: ACTUALIZADO 25/08/2025 | AI22: =+AI21+1 -> 21
A23: 726 | B23: ADECUACIÓN CAMBIO DE CALIBRE CTO. CHIVACOA | C23: CAMBIO DE CALIBRE CIRCUITO CHIVACOA A 336 MCM. S/E CHIVACOA | D23: CAMBIO DE CALIBRE CIRCUITO CHIVACOA EN 13,8 KV A CONDUCTOR 336 MCM DESDE S/E CHIVACOA HASTA ZONA CENTRAL DEL PUEBLO. S/E CHIVACOA | E23: PENDIENTE | F23: EL PROYECTO DE ADECUACIÓN DE LÍNEAS DE MEDIA TENSIÓN OPTIMIZA LA INFRAESTRUCTURA ELÉCTRICA MEDIANTE LA MODERNIZACIÓN DE CONDUCTORES, ESTRUCTURAS Y AISLADORES, MEJORANDO LA CAPACIDAD DE CARGA Y REDUCIENDO PÉRDIDAS POR EFECTO JOULE. SU IMPACTO SE TRADUCE EN *MAYOR EFICIENCIA ENERGÉTICA, REDUCCIÓN DE FALLAS Y AUMENTO DE LA CONFIABILIDAD DEL SISTEMA*, BENEFICIANDO TANTO A USUARIOS INDUSTRIALES COMO RESIDENCIALES, AL GARANTIZAR UNA DISTRIBUCIÓN ESTABLE Y SEGURA DE LA ENERGÍA. ADEMÁS, DISMINUYE COSTOS DE MANTENIMIENTO Y CONTRIBUYE A LA SOSTENIBILIDAD DEL SERVICIO ELÉCTRICO. | G23: 133813.75 | H23: 4 | I23: INGENIERIA CONCEPTUAL | J23: POR EJECUTAR | K23: CIRCUITO | L23: CHIVACOA | M23: 13,8 KV | N23: KM | O23: 3.5 | P23: YARACUY | Q23: BRUZUAL | R23: CHIVACOA | S23: 06/2027 | T23: 2027 | U23: 3/3/2027 | V23: 3/7/2027 | Y23: 133813.75 | AD23: =+"PRT-"&P23&"-"&AI23 -> PRT-YARACUY-22 | AE23: COP | AH23: ACTUALIZADO 25/08/2025 | AI23: =+AI22+1 -> 22
A24: 727 | B24: ADECUACIÓN CAMBIO DE CALIBRE CTO. AGUARUCA | C24: CAMBIO DE CALIBRE Y REUBICACIÓN CIRCUITO AGUARUCA EN 13,8 KV. S/E CHIVACOA | D24: CAMBIO DE CALIBRE Y REUBICACIÓN CIRCUITO AGUARUCA 13,8 KV, DESDE S/E CHIVACOA-FINAL AV SORTE- CALLE LOS LEONES CON AVDA 4 Y 5 (CENTRO CRISTIANO REDENCIÓN) HASTA AV. 4 CON CALLE 16 EN CHIVACOA. S/E CHIVACOA | E24: PENDIENTE | F24: EL PROYECTO DE ADECUACIÓN DE LÍNEAS DE MEDIA TENSIÓN OPTIMIZA LA INFRAESTRUCTURA ELÉCTRICA MEDIANTE LA MODERNIZACIÓN DE CONDUCTORES, ESTRUCTURAS Y AISLADORES, MEJORANDO LA CAPACIDAD DE CARGA Y REDUCIENDO PÉRDIDAS POR EFECTO JOULE. SU IMPACTO SE TRADUCE EN *MAYOR EFICIENCIA ENERGÉTICA, REDUCCIÓN DE FALLAS Y AUMENTO DE LA CONFIABILIDAD DEL SISTEMA*, BENEFICIANDO TANTO A USUARIOS INDUSTRIALES COMO RESIDENCIALES, AL GARANTIZAR UNA DISTRIBUCIÓN ESTABLE Y SEGURA DE LA ENERGÍA. ADEMÁS, DISMINUYE COSTOS DE MANTENIMIENTO Y CONTRIBUYE A LA SOSTENIBILIDAD DEL SERVICIO ELÉCTRICO. | G24: 152930 | H24: 3 | I24: INGENIERIA CONCEPTUAL | J24: POR EJECUTAR | K24: CIRCUITO | L24: CHIVACOA | M24: 13,8 KV | N24: KM | O24: 4 | P24: YARACUY | Q24: BRUZUAL | R24: CHIVACOA | S24: 04/2027 | T24: 2027 | U24: 3/3/2027 | V24: 3/6/2027 | Y24: 152930 | AD24: =+"PRT-"&P24&"-"&AI24 -> PRT-YARACUY-23 | AE24: COP | AH24: ACTUALIZADO 25/08/2025 | AI24: =+AI23+1 -> 23
A25: 728 | B25: ADECUACIÓN REUBICACIÓN CTO. CENTRAL YUQUERO Y PUEBLO NUEVO | C25: REUBICACIÓN DE CIRCUITOS CENTRAL YUQUERO Y PUEBLO NUEVO. S/E PALMASOLA | D25: REUBICACIÓN DE CIRCUITOS CENTRAL YUQUERO Y PUEBLO NUEVO EN 13,8 KV DE ACUERDO A PLAN DE CORTO PLAZO (UTE). CENTRAL YUQUERO: TRAMO CHARIPANO - LOS PLÁTANOS, VÍA LOS CAÑIZOS. PUEBLO NUEVO TRAMO KM 26- LAS CARACARAS. S/E PALMASOLA | E25: PENDIENTE | F25: EL PROYECTO DE ADECUACIÓN DE LÍNEAS DE MEDIA TENSIÓN OPTIMIZA LA INFRAESTRUCTURA ELÉCTRICA MEDIANTE LA MODERNIZACIÓN DE CONDUCTORES, ESTRUCTURAS Y AISLADORES, MEJORANDO LA CAPACIDAD DE CARGA Y REDUCIENDO PÉRDIDAS POR EFECTO JOULE. SU IMPACTO SE TRADUCE EN *MAYOR EFICIENCIA ENERGÉTICA, REDUCCIÓN DE FALLAS Y AUMENTO DE LA CONFIABILIDAD DEL SISTEMA*, BENEFICIANDO TANTO A USUARIOS INDUSTRIALES COMO RESIDENCIALES, AL GARANTIZAR UNA DISTRIBUCIÓN ESTABLE Y SEGURA DE LA ENERGÍA. ADEMÁS, DISMINUYE COSTOS DE MANTENIMIENTO Y CONTRIBUYE A LA SOSTENIBILIDAD DEL SERVICIO ELÉCTRICO. | G25: 65373.694 | H25: 6 | I25: INGENIERIA CONCEPTUAL | J25: POR EJECUTAR | K25: CIRCUITO | L25: PALMA SOLA | M25: 13,8 KV | N25: KM | O25: 12 | P25: YARACUY | Q25: VEROES | R25: PUEBLO NUEVO | S25: 08/2027 | T25: 2027 | U25: 3/3/2027 | V25: 3/9/2027 | Y25: 65373.694 | AD25: =+"PRT-"&P25&"-"&AI25 -> PRT-YARACUY-24 | AE25: COP | AH25: ACTUALIZADO 25/08/2025 | AI25: =+AI24+1 -> 24
A26: 729 | B26: ADECUACIÓN CAMBIO DE CALIBRE CTO. YUMARE EXPRESS - CRUCITO | C26: CAMBIO DE CALIBRE A 1/0 AL Y REUBICACIÓN CIRCUITO YUMARE EXPRESO. S/E PALMASOLA | D26: CAMBIO DE CALIBRE Y REUBICACIÓN CIRCUITO YUMARE EXPRESO 13,8 KV DE 6,8 KM (1/0) DERIVACIÓN CRUCITO-AGUA LINDA. S/E PALMASOLA | E26: PENDIENTE | F26: EL PROYECTO DE ADECUACIÓN DE LÍNEAS DE MEDIA TENSIÓN OPTIMIZA LA INFRAESTRUCTURA ELÉCTRICA MEDIANTE LA MODERNIZACIÓN DE CONDUCTORES, ESTRUCTURAS Y AISLADORES, MEJORANDO LA CAPACIDAD DE CARGA Y REDUCIENDO PÉRDIDAS POR EFECTO JOULE. SU IMPACTO SE TRADUCE EN *MAYOR EFICIENCIA ENERGÉTICA, REDUCCIÓN DE FALLAS Y AUMENTO DE LA CONFIABILIDAD DEL SISTEMA*, BENEFICIANDO TANTO A USUARIOS INDUSTRIALES COMO RESIDENCIALES, AL GARANTIZAR UNA DISTRIBUCIÓN ESTABLE Y SEGURA DE LA ENERGÍA. ADEMÁS, DISMINUYE COSTOS DE MANTENIMIENTO Y CONTRIBUYE A LA SOSTENIBILIDAD DEL SERVICIO ELÉCTRICO. | G26: 259981 | H26: 3 | I26: INGENIERIA CONCEPTUAL | J26: POR EJECUTAR | K26: CIRCUITO | L26: PALMA SOLA | M26: 13,8 KV | N26: KM | O26: 6.8 | P26: YARACUY | Q26: MANUEL MONGE | R26: YUMARE | S26: 08/2027 | T26: 2027 | U26: 3/3/2027 | V26: 3/6/2027 | Y26: 259981 | AD26: =+"PRT-"&P26&"-"&AI26 -> PRT-YARACUY-25 | AE26: COP | AH26: ACTUALIZADO 25/08/2025 | AI26: =+AI25+1 -> 25
A27: 730 | B27: ADECUACIÓN CAMBIO DE CALIBRE CTO. ZONA IND. CHIVACOA | C27: CAMBIO DE CALIBRE Y REUBICACIÓN CIRCUITO ZONA INDUSTRIAL (S/E CHIVACOA) DESDE S/E HASTA FINAL AV SORTE EN CHIVACOA. | D27: CAMBIO DE CALIBRE Y REUBICACIÓN CIRCUITO ZONA INDUSTRIAL 13,8 KV CONDUCTOR 1/0 A 336 MCM (APROX. 0,2 KM DE LA S/E CHIVACOA). | E27: PENDIENTE | F27: EL PROYECTO DE ADECUACIÓN DE LÍNEAS DE MEDIA TENSIÓN OPTIMIZA LA INFRAESTRUCTURA ELÉCTRICA MEDIANTE LA MODERNIZACIÓN DE CONDUCTORES, ESTRUCTURAS Y AISLADORES, MEJORANDO LA CAPACIDAD DE CARGA Y REDUCIENDO PÉRDIDAS POR EFECTO JOULE. SU IMPACTO SE TRADUCE EN *MAYOR EFICIENCIA ENERGÉTICA, REDUCCIÓN DE FALLAS Y AUMENTO DE LA CONFIABILIDAD DEL SISTEMA*, BENEFICIANDO TANTO A USUARIOS INDUSTRIALES COMO RESIDENCIALES, AL GARANTIZAR UNA DISTRIBUCIÓN ESTABLE Y SEGURA DE LA ENERGÍA. ADEMÁS, DISMINUYE COSTOS DE MANTENIMIENTO Y CONTRIBUYE A LA SOSTENIBILIDAD DEL SERVICIO ELÉCTRICO. | G27: 7646.5 | H27: 4 | I27: INGENIERIA CONCEPTUAL | J27: POR EJECUTAR | K27: CIRCUITO | L27: CHIVACOA | M27: 13,8 KV | N27: KM | O27: 0.2 | P27: YARACUY | Q27: BRUZUAL | R27: CHIVACOA | S27: 10/2025 | T27: 2026 | X27: 7646.5 | AD27: =+"PRT-"&P27&"-"&AI27 -> PRT-YARACUY-26 | AE27: COP | AH27: ACTUALIZADO 25/08/2025 | AI27: =+AI26+1 -> 26
A28: 731 | B28: ADECUACIÓN REUBICACIÓN CTO. CAYURE | C28: REUBICACIÓN DE CIRCUITO CAYURE EN 13,8 KV. S/E AROA | D28: REUBICACIÓN CIRCUITO CAYURE 13,8 KV LINEA TRONCAL 4 KM (AL 1/0) DESDE SECTOR ATASCADERO HASTA POBLADO CAYURE Y 2,1 KM DESDE FINCA LOS SÁNCHEZ HASTA DERIVACIÓN SAN JOSÉ. S/E AROA | E28: PENDIENTE | F28: EL PROYECTO DE ADECUACIÓN DE LÍNEAS DE MEDIA TENSIÓN OPTIMIZA LA INFRAESTRUCTURA ELÉCTRICA MEDIANTE LA MODERNIZACIÓN DE CONDUCTORES, ESTRUCTURAS Y AISLADORES, MEJORANDO LA CAPACIDAD DE CARGA Y REDUCIENDO PÉRDIDAS POR EFECTO JOULE. SU IMPACTO SE TRADUCE EN *MAYOR EFICIENCIA ENERGÉTICA, REDUCCIÓN DE FALLAS Y AUMENTO DE LA CONFIABILIDAD DEL SISTEMA*, BENEFICIANDO TANTO A USUARIOS INDUSTRIALES COMO RESIDENCIALES, AL GARANTIZAR UNA DISTRIBUCIÓN ESTABLE Y SEGURA DE LA ENERGÍA. ADEMÁS, DISMINUYE COSTOS DE MANTENIMIENTO Y CONTRIBUYE A LA SOSTENIBILIDAD DEL SERVICIO ELÉCTRICO. | G28: 33231.628 | H28: 3 | I28: INGENIERIA CONCEPTUAL | J28: POR EJECUTAR | K28: CIRCUITO | L28: AROA | M28: 13,8 KV | N28: KM | O28: 2.1 | P28: YARACUY | Q28: BOLÍVAR | R28: AROA | S28: 10/2027 | T28: 2027 | U28: 3/3/2027 | V28: 3/6/2027 | Y28: 33231.628 | AD28: =+"PRT-"&P28&"-"&AI28 -> PRT-YARACUY-27 | AE28: COP | AH28: ACTUALIZADO 25/08/2025 | AI28: =+AI27+1 -> 27
A29: 732 | B29: ADECUACIÓN REUBICACIÓN Y CAMBIO DE CALIBRE, CTO. CAÑAVERAL | C29: REUBICACIÓN Y CAMBIO DE CALIBRE N 6 DE COBRE A 1/0 ALUMINIO, SECTOR LAS MERCEDES SAN JOSÉ. CTO. CAÑAVERAL, S/E INDEPENDENCIA | D29: REUBICACIÓN Y CAMBIO DE CALIBRE N 6 DE COBRE A 1/0 ALUMINIO TRAMO CIRCUITO CAÑAVERAL EN 12,47 KV, SECTOR LAS MERCEDES SAN JOSÉ. S/E SAN FELIPE 2 | E29: PENDIENTE | F29: EL PROYECTO DE ADECUACIÓN DE LÍNEAS DE MEDIA TENSIÓN OPTIMIZA LA INFRAESTRUCTURA ELÉCTRICA MEDIANTE LA MODERNIZACIÓN DE CONDUCTORES, ESTRUCTURAS Y AISLADORES, MEJORANDO LA CAPACIDAD DE CARGA Y REDUCIENDO PÉRDIDAS POR EFECTO JOULE. SU IMPACTO SE TRADUCE EN *MAYOR EFICIENCIA ENERGÉTICA, REDUCCIÓN DE FALLAS Y AUMENTO DE LA CONFIABILIDAD DEL SISTEMA*, BENEFICIANDO TANTO A USUARIOS INDUSTRIALES COMO RESIDENCIALES, AL GARANTIZAR UNA DISTRIBUCIÓN ESTABLE Y SEGURA DE LA ENERGÍA. ADEMÁS, DISMINUYE COSTOS DE MANTENIMIENTO Y CONTRIBUYE A LA SOSTENIBILIDAD DEL SERVICIO ELÉCTRICO. | G29: 202632.25 | H29: 2 | I29: INGENIERIA CONCEPTUAL | J29: POR EJECUTAR | K29: CIRCUITO | L29: INDEPENDENCIA | M29: 12,47 KV | N29: KM | O29: 5.3 | P29: YARACUY | Q29: SAN FELIPE | R29: SAN FELIPE | S29: 07/2026 | T29: 2026 | U29: 3/3/2026 | V29: 3/5/2026 | X29: 202632.25 | AD29: =+"PRT-"&P29&"-"&AI29 -> PRT-YARACUY-28 | AE29: COP | AH29: ACTUALIZADO 25/08/2025 | AI29: =+AI28+1 -> 28
A30: 733 | B30: ADECUACIÓN REUBICACIÓN DE LINEAS CTO. EL GUAYABO | C30: REUBICACIÓN DE LINEA EN MT. (12,47 KV) TRAMO GUABINA - LA YUCA. S/E CARBONERO | D30: REUBICACIÓN DE LINEA EN MT. DEL CIRCUITO EL GUAYABO (12,47 KV) TRAMO GUABINA - LA YUCA CALIBRE 1/0. S/E CARBONERO | E30: PENDIENTE | F30: EL PROYECTO DE ADECUACIÓN DE LÍNEAS DE MEDIA TENSIÓN OPTIMIZA LA INFRAESTRUCTURA ELÉCTRICA MEDIANTE LA MODERNIZACIÓN DE CONDUCTORES, ESTRUCTURAS Y AISLADORES, MEJORANDO LA CAPACIDAD DE CARGA Y REDUCIENDO PÉRDIDAS POR EFECTO JOULE. SU IMPACTO SE TRADUCE EN *MAYOR EFICIENCIA ENERGÉTICA, REDUCCIÓN DE FALLAS Y AUMENTO DE LA CONFIABILIDAD DEL SISTEMA*, BENEFICIANDO TANTO A USUARIOS INDUSTRIALES COMO RESIDENCIALES, AL GARANTIZAR UNA DISTRIBUCIÓN ESTABLE Y SEGURA DE LA ENERGÍA. ADEMÁS, DISMINUYE COSTOS DE MANTENIMIENTO Y CONTRIBUYE A LA SOSTENIBILIDAD DEL SERVICIO ELÉCTRICO. | G30: 32686.847 | H30: 2 | I30: INGENIERIA CONCEPTUAL | J30: POR EJECUTAR | K30: CIRCUITO | L30: CARBONERO | M30: 12,47 KV | N30: KM | O30: 5.7 | P30: YARACUY | Q30: VEROES | R30: CARBONERO | S30: 05/2026 | T30: 2026 | U30: 3/3/2026 | V30: 3/5/2026 | X30: 32686.847 | AD30: =+"PRT-"&P30&"-"&AI30 -> PRT-YARACUY-29 | AE30: COP | AH30: ACTUALIZADO 25/08/2025 | AI30: =+AI29+1 -> 29
A31: 734 | B31: ADECUACIÓN CAMBIO DE CALIBRE CTO. SAN JAVIER | C31: CAMBIO DE CALIBRE ALUMINIO 1/0 A 4/0 Y EXTENSIÓN DE LINEA 4/0. SECTOR EL PAUJI Y MARÍN. S/E INDEPENDENCIA | D31: CAMBIO DE CALIBRE ALUMINIO 1/0 A 4/0 Y EXTENSIÓN DE LINEA 4/0 EN EL CIRCUITO SAN JAVIER. SECTOR EL PAUJI Y MARÍN. | E31: PENDIENTE | F31: EL PROYECTO DE ADECUACIÓN DE LÍNEAS DE MEDIA TENSIÓN OPTIMIZA LA INFRAESTRUCTURA ELÉCTRICA MEDIANTE LA MODERNIZACIÓN DE CONDUCTORES, ESTRUCTURAS Y AISLADORES, MEJORANDO LA CAPACIDAD DE CARGA Y REDUCIENDO PÉRDIDAS POR EFECTO JOULE. SU IMPACTO SE TRADUCE EN *MAYOR EFICIENCIA ENERGÉTICA, REDUCCIÓN DE FALLAS Y AUMENTO DE LA CONFIABILIDAD DEL SISTEMA*, BENEFICIANDO TANTO A USUARIOS INDUSTRIALES COMO RESIDENCIALES, AL GARANTIZAR UNA DISTRIBUCIÓN ESTABLE Y SEGURA DE LA ENERGÍA. ADEMÁS, DISMINUYE COSTOS DE MANTENIMIENTO Y CONTRIBUYE A LA SOSTENIBILIDAD DEL SERVICIO ELÉCTRICO. | G31: 107051 | H31: 3 | I31: INGENIERIA CONCEPTUAL | J31: POR EJECUTAR | K31: CIRCUITO | L31: CARBONERO | M31: 12,47 KV | N31: KM | O31: 2.8 | P31: YARACUY | Q31: VEROES | R31: CARBONERO | S31: 08/2027 | T31: 2027 | U31: 3/3/2027 | V31: 3/6/2027 | Y31: 107051 | AD31: =+"PRT-"&P31&"-"&AI31 -> PRT-YARACUY-30 | AE31: COP | AH31: ACTUALIZADO 25/08/2025 | AI31: =+AI30+1 -> 30
A32: 735 | B32: ADECUACIÓN CAMBIO DE HERRAJES Y AISLADORES, CTO. PALMA SOLA | C32: REHABILITACION MAYOR SUSTITUCIÓN DE COMPONENTES OBSOLETOS, CIRCUITO PALMASOLA. S/E PALMASOLA | D32: MANTENIMIENTO INTEGRAL CIRCUITO PALMASOLA 13,8 KV DE APROXIMADO 40 KM TRONCAL Y DERIVACIÓN CAMBIO DE HERRAJES, AISLADORES, PARARRAYOS, ESTRUCTURA Y POSTES. S/E PALMASOLA | E32: PENDIENTE | F32: EL PROYECTO DE ADECUACIÓN DE LÍNEAS DE MEDIA TENSIÓN OPTIMIZA LA INFRAESTRUCTURA ELÉCTRICA MEDIANTE LA MODERNIZACIÓN DE CONDUCTORES, ESTRUCTURAS Y AISLADORES, MEJORANDO LA CAPACIDAD DE CARGA Y REDUCIENDO PÉRDIDAS POR EFECTO JOULE. SU IMPACTO SE TRADUCE EN *MAYOR EFICIENCIA ENERGÉTICA, REDUCCIÓN DE FALLAS Y AUMENTO DE LA CONFIABILIDAD DEL SISTEMA*, BENEFICIANDO TANTO A USUARIOS INDUSTRIALES COMO RESIDENCIALES, AL GARANTIZAR UNA DISTRIBUCIÓN ESTABLE Y SEGURA DE LA ENERGÍA. ADEMÁS, DISMINUYE COSTOS DE MANTENIMIENTO Y CONTRIBUYE A LA SOSTENIBILIDAD DEL SERVICIO ELÉCTRICO. | G32: 145274.88 | H32: 3 | I32: INGENIERIA CONCEPTUAL | J32: POR EJECUTAR | K32: CIRCUITO | L32: PALMA SOLA | M32: 13,8 KV | N32: KM | O32: 20 | P32: YARACUY | Q32: MANUEL MONGE, PALMASOLA, VEROES | R32: YUMARE | S32: 08/2028 | T32: 2028 | U32: 3/3/2028 | V32: 3/6/2028 | Z32: 145274.88 | AD32: =+"PRT-"&P32&"-"&AI32 -> PRT-YARACUY-31 | AE32: COP | AH32: ACTUALIZADO 25/08/2025 | AI32: =+AI31+1 -> 31
A33: 736 | B33: ADECUACIÓN REUBICACIÓN DE LINEAS Y CAMBIO DE CALIBRE, CTO. AROA - TIERRA FRÍA | C33: REHABILITACION MAYOR CIRCUITO AROA. S/E AROA | D33: MANTENIMIENTO INTEGRAL CIRCUITO AROA 13,8 KV DE APROXIMADO 20 KM DERIVACIÓN TIERRA FRÍA: CAMBIO DE HERRAJES, AISLADORES, PARARRAYOS Y POSTES. S/E AROA | E33: PENDIENTE | F33: EL PROYECTO DE ADECUACIÓN DE LÍNEAS DE MEDIA TENSIÓN OPTIMIZA LA INFRAESTRUCTURA ELÉCTRICA MEDIANTE LA MODERNIZACIÓN DE CONDUCTORES, ESTRUCTURAS Y AISLADORES, MEJORANDO LA CAPACIDAD DE CARGA Y REDUCIENDO PÉRDIDAS POR EFECTO JOULE. SU IMPACTO SE TRADUCE EN *MAYOR EFICIENCIA ENERGÉTICA, REDUCCIÓN DE FALLAS Y AUMENTO DE LA CONFIABILIDAD DEL SISTEMA*, BENEFICIANDO TANTO A USUARIOS INDUSTRIALES COMO RESIDENCIALES, AL GARANTIZAR UNA DISTRIBUCIÓN ESTABLE Y SEGURA DE LA ENERGÍA. ADEMÁS, DISMINUYE COSTOS DE MANTENIMIENTO Y CONTRIBUYE A LA SOSTENIBILIDAD DEL SERVICIO ELÉCTRICO. | G33: 764650 | H33: 6 | I33: INGENIERIA CONCEPTUAL | J33: POR EJECUTAR | K33: CIRCUITO | L33: AROA | M33: 13,8 KV | N33: KM | O33: 20 | P33: YARACUY | Q33: BOLÍVAR | R33: AROA | S33: 04/2027 | T33: 2027 | U33: 3/3/2027 | V33: 3/9/2027 | Y33: 764650 | AD33: =+"PRT-"&P33&"-"&AI33 -> PRT-YARACUY-32 | AE33: COP | AH33: ACTUALIZADO 25/08/2025 | AI33: =+AI32+1 -> 32
A34: 737 | B34: ADECUACIÓN CAMBIO DE CALIBRE CTO. AROA - CERRO NEGRO | C34: CAMBIO DE CALIBRE CIRCUITO AROA. S/E AROA | D34: CAMBIO DE CALIBRE CIRCUITO AROA 13,8 KV DE APROXIMADO 18,75 KM. DE CALIBRE 2/0 AL DESDE TIERRA FRÍA HASTA CERRO NEGRO. S/E AROA | E34: PENDIENTE | F34: EL PROYECTO DE ADECUACIÓN DE LÍNEAS DE MEDIA TENSIÓN OPTIMIZA LA INFRAESTRUCTURA ELÉCTRICA MEDIANTE LA MODERNIZACIÓN DE CONDUCTORES, ESTRUCTURAS Y AISLADORES, MEJORANDO LA CAPACIDAD DE CARGA Y REDUCIENDO PÉRDIDAS POR EFECTO JOULE. SU IMPACTO SE TRADUCE EN *MAYOR EFICIENCIA ENERGÉTICA, REDUCCIÓN DE FALLAS Y AUMENTO DE LA CONFIABILIDAD DEL SISTEMA*, BENEFICIANDO TANTO A USUARIOS INDUSTRIALES COMO RESIDENCIALES, AL GARANTIZAR UNA DISTRIBUCIÓN ESTABLE Y SEGURA DE LA ENERGÍA. ADEMÁS, DISMINUYE COSTOS DE MANTENIMIENTO Y CONTRIBUYE A LA SOSTENIBILIDAD DEL SERVICIO ELÉCTRICO. | G34: 716859.38 | H34: 6 | I34: INGENIERIA CONCEPTUAL | J34: POR EJECUTAR | K34: CIRCUITO | L34: AROA | M34: 13,8 KV | N34: KM | O34: 18.75 | P34: YARACUY | Q34: BOLÍVAR | R34: AROA | S34: 7/2027 | T34: 2027 | U34: 3/3/2027 | V34: 3/9/2027 | Y34: 716859.38 | AD34: =+"PRT-"&P34&"-"&AI34 -> PRT-YARACUY-33 | AE34: COP | AH34: ACTUALIZADO 25/08/2025 | AI34: =+AI33+1 -> 33
A35: 738 | B35: ADECUACIÓN CAMBIO DE CALIBRE CTO. CERÁMICAS CARIBE | C35: CAMBIO DE CALIBRE CIRCUITO CERÁMICAS CARIBE EN 13,8 KV. S/E CHIVACOA | D35: CAMBIO DE CALIBRE CIRCUITO CERÁMICAS CARIBE CONDUCTOR 1/0 A 336 MCM DESDE S/E CHIVACOA (APROX. 0,8 KM) | E35: PENDIENTE | F35: EL PROYECTO DE ADECUACIÓN DE LÍNEAS DE MEDIA TENSIÓN OPTIMIZA LA INFRAESTRUCTURA ELÉCTRICA MEDIANTE LA MODERNIZACIÓN DE CONDUCTORES, ESTRUCTURAS Y AISLADORES, MEJORANDO LA CAPACIDAD DE CARGA Y REDUCIENDO PÉRDIDAS POR EFECTO JOULE. SU IMPACTO SE TRADUCE EN *MAYOR EFICIENCIA ENERGÉTICA, REDUCCIÓN DE FALLAS Y AUMENTO DE LA CONFIABILIDAD DEL SISTEMA*, BENEFICIANDO TANTO A USUARIOS INDUSTRIALES COMO RESIDENCIALES, AL GARANTIZAR UNA DISTRIBUCIÓN ESTABLE Y SEGURA DE LA ENERGÍA. ADEMÁS, DISMINUYE COSTOS DE MANTENIMIENTO Y CONTRIBUYE A LA SOSTENIBILIDAD DEL SERVICIO ELÉCTRICO. | G35: 30586 | H35: 1 | I35: INGENIERIA CONCEPTUAL | J35: POR EJECUTAR | K35: CIRCUITO | L35: CHIVACOA | M35: 13,8 KV | N35: KM | O35: 0.8 | P35: YARACUY | Q35: BRUZUAL | R35: CHIVACOA | S35: 10/2025 | T35: 2026 | X35: 30586 | AD35: =+"PRT-"&P35&"-"&AI35 -> PRT-YARACUY-34 | AE35: COP | AH35: ACTUALIZADO 25/08/2025 | AI35: =+AI34+1 -> 34
A36: 739 | B36: EXTENSIÓN DE LINEA CAMBIO DE CALIBRE CTO. EL ROSARIO | C36: EXTENSIÓN DEL CIRCUITO EL ROSARIO. S/E CHIVACOA | D36: EXTENSIÓN DE CIRCUITO EL ROSARIO POR AMPLIACIÓN DE LÍNEA 34,5 KV DESDE LOS COGOLLOS HASTA LA GUÁSIMA | E36: PENDIENTE | F36: EL PROYECTO DE ADECUACIÓN DE LÍNEAS DE MEDIA TENSIÓN OPTIMIZA LA INFRAESTRUCTURA ELÉCTRICA MEDIANTE LA MODERNIZACIÓN DE CONDUCTORES, ESTRUCTURAS Y AISLADORES, MEJORANDO LA CAPACIDAD DE CARGA Y REDUCIENDO PÉRDIDAS POR EFECTO JOULE. SU IMPACTO SE TRADUCE EN *MAYOR EFICIENCIA ENERGÉTICA, REDUCCIÓN DE FALLAS Y AUMENTO DE LA CONFIABILIDAD DEL SISTEMA*, BENEFICIANDO TANTO A USUARIOS INDUSTRIALES COMO RESIDENCIALES, AL GARANTIZAR UNA DISTRIBUCIÓN ESTABLE Y SEGURA DE LA ENERGÍA. ADEMÁS, DISMINUYE COSTOS DE MANTENIMIENTO Y CONTRIBUYE A LA SOSTENIBILIDAD DEL SERVICIO ELÉCTRICO. | G36: 103227.75 | H36: 2 | I36: INGENIERIA CONCEPTUAL | J36: POR EJECUTAR | K36: CIRCUITO | L36: CHIVACOA | M36: 13,8 KV | N36: KM | O36: 2.7 | P36: YARACUY | Q36: BRUZUAL | R36: CHIVACOA | S36: 3/2026 | T36: 2026 | U36: 3/3/2026 | V36: 3/5/2026 | X36: 103227.75 | AD36: =+"PRT-"&P36&"-"&AI36 -> PRT-YARACUY-35 | AE36: COP | AH36: ACTUALIZADO 25/08/2025 | AI36: =+AI35+1 -> 35
A37: 740 | B37: ADECUACIÓN CAMBIO DE CALIBRE CTO. GOBERNACIÓN | C37: CAMBIO DE CALIBRE DE UN TRAMO DE CIRCUITO GOBERNACIÓN EN 12,47 KV DE APROXIMADO 2,3KM DE LINEA AÉREA AL 1/0 POR AL 4/0 SECTOR JOBITO. S/E INDEPENDENCIA | D37: CAMBIO DE CALIBRE DE UN TRAMO DEL CIRCUITO GOBERNACIÓN (12,47 KV) DE 2,3KM DE LINEA AÉREA AL 1/0 POR AL 4/0 SECTOR JOBITO. S/E INDEPENDENCIA | E37: PENDIENTE | F37: EL PROYECTO DE ADECUACIÓN DE LÍNEAS DE MEDIA TENSIÓN OPTIMIZA LA INFRAESTRUCTURA ELÉCTRICA MEDIANTE LA MODERNIZACIÓN DE CONDUCTORES, ESTRUCTURAS Y AISLADORES, MEJORANDO LA CAPACIDAD DE CARGA Y REDUCIENDO PÉRDIDAS POR EFECTO JOULE. SU IMPACTO SE TRADUCE EN *MAYOR EFICIENCIA ENERGÉTICA, REDUCCIÓN DE FALLAS Y AUMENTO DE LA CONFIABILIDAD DEL SISTEMA*, BENEFICIANDO TANTO A USUARIOS INDUSTRIALES COMO RESIDENCIALES, AL GARANTIZAR UNA DISTRIBUCIÓN ESTABLE Y SEGURA DE LA ENERGÍA. ADEMÁS, DISMINUYE COSTOS DE MANTENIMIENTO Y CONTRIBUYE A LA SOSTENIBILIDAD DEL SERVICIO ELÉCTRICO. | G37: 87934.75 | H37: 2 | I37: INGENIERIA CONCEPTUAL | J37: POR EJECUTAR | K37: CIRCUITO | L37: INDEPENDENCIA | M37: 12,47 KV | N37: KM | O37: 2.3 | P37: YARACUY | Q37: SAN FELIPE | R37: SAN FELIPE | S37: 05/2026 | T37: 2026 | U37: 3/3/2026 | V37: 3/5/2026 | X37: 87934.75 | AD37: =+"PRT-"&P37&"-"&AI37 -> PRT-YARACUY-36 | AE37: COP | AH37: ACTUALIZADO 25/08/2025 | AI37: =+AI36+1 -> 36
A38: 741 | B38: ADECUACIÓN DE MEDIA TENSIÓN DE PARTE DEL CTO. CAYURE (PALO QUEMAO) Y TRANSFERIR AL CTO. MARIN | C38: ADECUACIÓN MEDIA TENSIÓN SECTOR PALO QUEMAO-GUARAPO CTO. MARIN | D38: ADECUACIÓN EN MEDIA Y BAJA TENSIÓN DEL SECTOR PALO QUEMAO-GUARAPO A NORMAS EDC, Y CONEXIÓN AL CIRCUITO EN 12,47 KV | E38: PENDIENTE | F38: EL PROYECTO DE ADECUACIÓN DE LÍNEAS DE MEDIA TENSIÓN OPTIMIZA LA INFRAESTRUCTURA ELÉCTRICA MEDIANTE LA MODERNIZACIÓN DE CONDUCTORES, ESTRUCTURAS Y AISLADORES, MEJORANDO LA CAPACIDAD DE CARGA Y REDUCIENDO PÉRDIDAS POR EFECTO JOULE. SU IMPACTO SE TRADUCE EN *MAYOR EFICIENCIA ENERGÉTICA, REDUCCIÓN DE FALLAS Y AUMENTO DE LA CONFIABILIDAD DEL SISTEMA*, BENEFICIANDO TANTO A USUARIOS INDUSTRIALES COMO RESIDENCIALES, AL GARANTIZAR UNA DISTRIBUCIÓN ESTABLE Y SEGURA DE LA ENERGÍA. ADEMÁS, DISMINUYE COSTOS DE MANTENIMIENTO Y CONTRIBUYE A LA SOSTENIBILIDAD DEL SERVICIO ELÉCTRICO. | G38: 23346.511 | H38: 3 | I38: INGENIERIA CONCEPTUAL | J38: POR EJECUTAR | K38: CIRCUITO | L38: INDEPENDENCIA | M38: 12,47 KV | N38: KM | O38: 1.2 | P38: YARACUY | Q38: SAN FELIPE | R38: SAN FELIPE | S38: 08/2026 | T38: 2026 | U38: 3/3/2026 | V38: 3/6/2026 | X38: 23346.511 | AD38: =+"PRT-"&P38&"-"&AI38 -> PRT-YARACUY-37 | AE38: COP | AH38: ACTUALIZADO 25/08/2025 | AI38: =+AI37+1 -> 37
A39: 742 | B39: ADECUACIÓN DE MEDIA TENSIÓN DE PARTE DEL CTO. CAYURE (CAÑIZOS) Y TRANSFERIR CTO. MARIN. | C39: ADECUACIÓN MEDIA TENSIÓN SECTOR LOS CAÑIZOS EN EL GUAYABO EN VEROES. CTO. MARIN | D39: ADECUACIÓN EN MEDIA Y BAJA TENSIÓN DEL SECTOR LOS CAÑIZOS A NORMAS EDC, Y CONEXIÓN AL CIRCUITO MARIN EN 12,47 KV EN EL GUAYABO EN VEROES | E39: PENDIENTE | F39: EL PROYECTO DE ADECUACIÓN DE LÍNEAS DE MEDIA TENSIÓN OPTIMIZA LA INFRAESTRUCTURA ELÉCTRICA MEDIANTE LA MODERNIZACIÓN DE CONDUCTORES, ESTRUCTURAS Y AISLADORES, MEJORANDO LA CAPACIDAD DE CARGA Y REDUCIENDO PÉRDIDAS POR EFECTO JOULE. SU IMPACTO SE TRADUCE EN *MAYOR EFICIENCIA ENERGÉTICA, REDUCCIÓN DE FALLAS Y AUMENTO DE LA CONFIABILIDAD DEL SISTEMA*, BENEFICIANDO TANTO A USUARIOS INDUSTRIALES COMO RESIDENCIALES, AL GARANTIZAR UNA DISTRIBUCIÓN ESTABLE Y SEGURA DE LA ENERGÍA. ADEMÁS, DISMINUYE COSTOS DE MANTENIMIENTO Y CONTRIBUYE A LA SOSTENIBILIDAD DEL SERVICIO ELÉCTRICO. | G39: 48047.19 | H39: 4 | I39: INGENIERIA CONCEPTUAL | J39: POR EJECUTAR | K39: CIRCUITO | L39: CARBONERO | M39: 12,47 KV | N39: KM | O39: 1.7 | P39: YARACUY | Q39: VEROES | R39: CARBONERO | S39: 05/2026 | T39: 2026 | U39: 3/3/2026 | V39: 3/7/2026 | X39: 48047.19 | AD39: =+"PRT-"&P39&"-"&AI39 -> PRT-YARACUY-38 | AE39: COP | AH39: ACTUALIZADO 25/08/2025 | AI39: =+AI38+1 -> 38
A40: 743 | B40: REGULACIÓN DE VOLTAJE CTO. SAN PABLO Y CTO. MARIN | C40: INSTALACIÓN DE 2 JUEGOS DE REGULADORES 12,47 KV EN LÍNEAS DE MT PARA LOS SECTORES DE SAN PABLO Y MARÍN. S/E INDEPENDENCIA Y CARBONERO | D40: INSTALACIÓN DE 2 JUEGOS DE REGULADORES 12,47 KV EN LÍNEAS DE MT PARA LOS SECTORES DE SAN PABLO Y MARÍN. INDEPENDENCIA Y CARBONERO | E40: PENDIENTE | F40: LA INSTALACIÓN DE SISTEMAS DE REGULACIÓN DE VOLTAJE EN MEDIA TENSIÓN *OPTIMIZA LA ESTABILIDAD Y CALIDAD DEL SUMINISTRO ELÉCTRICO, REDUCIENDO FLUCTUACIONES Y MEJORANDO LA EFICIENCIA ENERGÉTICA*. ESTO PROTEGE EQUIPOS SENSIBLES, MINIMIZA PÉRDIDAS Y GARANTIZA UNA DISTRIBUCIÓN CONFIABLE, BENEFICIANDO TANTO A USUARIOS INDUSTRIALES COMO COMERCIALES. | G40: 182250 | H40: 1 | I40: INGENIERIA CONCEPTUAL | J40: POR EJECUTAR | K40: CIRCUITO | L40: INDEPENDENCIA | M40: 12,47 KV | N40: MVA | O40: 1.5 | P40: YARACUY | Q40: ARISTIDES BASTIDAS/SAN FELIPE | R40: SAN FELIPE | S40: 04/2026 | T40: 2026 | U40: 3/3/2026 | V40: 3/4/2026 | X40: 182250 | AD40: =+"PRT-"&P40&"-"&AI40 -> PRT-YARACUY-39 | AE40: COP | AH40: ACTUALIZADO 25/08/2025 | AI40: =+AI39+1 -> 39
...

Sheet CONSULTA FICHA PROYECTO
A1: PRT-ESTADO-NNN
A2: PRT-YARACUY-24
A3: ESTADO | B3: MUNICIPIO | C3: DIRECCION | E3: SITUACION ACTUAL DEL PROYECTO | F3: FASE DEL PROYECTO | G3: TIPO DE INSTALACIÓN | H3: NOMBRE DE LA INSTALACIÓN | I3: NIVEL DE TENSIÓN | J3: UNIDAD DE MEDIDA ( MVA, MW, km) | K3: CAPACIDAD KM o MVAR
A4: =_xlfn.XLOOKUP(A2,'PRTSEN YARACUY (ACTUALIZADO)'!AD1:AD73,'PRTSEN YARACUY (ACTUALIZADO)'!P1:P73,"NO EXISTE",0) -> #NAME? | B4: =_xlfn.XLOOKUP(A2,'PRTSEN YARACUY (ACTUALIZADO)'!AD1:AD73,'PRTSEN YARACUY (ACTUALIZADO)'!Q1:Q73,"NO EXISTE",0) -> #NAME? | C4: =_xlfn.XLOOKUP(A2,'PRTSEN YARACUY (ACTUALIZADO)'!AD1:AD73,'PRTSEN YARACUY (ACTUALIZADO)'!R1:R73,"NO EXISTE",0) -> #NAME? | E4: =_xlfn.XLOOKUP(A2,'PRTSEN YARACUY (ACTUALIZADO)'!AD1:AD73,'PRTSEN YARACUY (ACTUALIZADO)'!E1:E73,"NO EXISTE",0) -> #NAME? | F4: =_xlfn.XLOOKUP(A2,'PRTSEN YARACUY (ACTUALIZADO)'!AD1:AD73,'PRTSEN YARACUY (ACTUALIZADO)'!I1:I73,"NO EXISTE",0) -> #NAME? | G4: =_xlfn.XLOOKUP(A2,'PRTSEN YARACUY (ACTUALIZADO)'!AD1:AD73,'PRTSEN YARACUY (ACTUALIZADO)'!K1:K73,"NO EXISTE",0) -> #NAME? | H4: =_xlfn.XLOOKUP(A2,'PRTSEN YARACUY (ACTUALIZADO)'!AD1:AD73,'PRTSEN YARACUY (ACTUALIZADO)'!L1:L73,"NO EXISTE",0) -> #NAME? | I4: =_xlfn.XLOOKUP(A2,'PRTSEN YARACUY (ACTUALIZADO)'!AD1:AD73,'PRTSEN YARACUY (ACTUALIZADO)'!M1:M73,"NO EXISTE",0) -> #NAME? | J4: =_xlfn.XLOOKUP(A2,'PRTSEN YARACUY (ACTUALIZADO)'!AD1:AD73,'PRTSEN YARACUY (ACTUALIZADO)'!N1:N73,"NO EXISTE",0) -> #NAME? | K4: =_xlfn.XLOOKUP(A2,'PRTSEN YARACUY (ACTUALIZADO)'!AD1:AD73,'PRTSEN YARACUY (ACTUALIZADO)'!O1:O73,"NO EXISTE",0) -> #NAME?
A5: NOMBRE DEL PROYECTO | E5: FOTOGRAFIA
A6: =_xlfn.XLOOKUP(A2,'PRTSEN YARACUY (ACTUALIZADO)'!AD1:AD73,'PRTSEN YARACUY (ACTUALIZADO)'!B1:B73,"NO EXISTE",0) -> #NAME?
A7: DESCRIPCION DEL PROYECTO
A8: =_xlfn.XLOOKUP(A2,'PRTSEN YARACUY (ACTUALIZADO)'!AD1:AD73,'PRTSEN YARACUY (ACTUALIZADO)'!C1:C73,"NO EXISTE",0) -> #NAME?
A9: ALCANCE DEL PROYECTO
A10: =_xlfn.XLOOKUP(A2,'PRTSEN YARACUY (ACTUALIZADO)'!AD1:AD73,'PRTSEN YARACUY (ACTUALIZADO)'!D1:D73,"NO EXISTE",0) -> #NAME?
A11: IMPACTO PARA EL SEN
A12: =_xlfn.XLOOKUP(A2,'PRTSEN YARACUY (ACTUALIZADO)'!AD1:AD73,'PRTSEN YARACUY (ACTUALIZADO)'!F1:F73,"NO EXISTE",0) -> #NAME?
A13: NÙMERO DE FAMILIAS BENEFICIADAS
A15: PERIODO DE EJECUCIÓN | B15: LAPSO DE EJECUCION (EN MESES) | C15: INICIO | D15: FIN
B16: =(YEAR(D16)-YEAR(C16))*12 + MONTH(D16)-MONTH(C16) -> #NAME? | C16: =_xlfn.XLOOKUP(A2,'PRTSEN YARACUY (ACTUALIZADO)'!AD1:AD73,'PRTSEN YARACUY (ACTUALIZADO)'!U1:U73,"SIN FECHA",0) -> #NAME? | D16: =_xlfn.XLOOKUP(A2,'PRTSEN YARACUY (ACTUALIZADO)'!AD1:AD73,'PRTSEN YARACUY (ACTUALIZADO)'!V1:V73,"SIN FECHA",0) -> #NAME?
A17: MONTO DE INVERSION ($) | B17: =_xlfn.XLOOKUP(A2,'PRTSEN YARACUY (ACTUALIZADO)'!AD1:AD73,'PRTSEN YARACUY (ACTUALIZADO)'!G1:G73,"SIN CALCULOS",0) -> #NAME? | C17: FUENTE DE FINANCIAMIENTO | E17: 2025 | F17: 2026 | G17: 2027 | H17: 2028 | I17: 2029 | J17: 2030 | K17: 2031
E18: =_xlfn.XLOOKUP($A$2,'PRTSEN YARACUY (ACTUALIZADO)'!$AD$1:$AD$73,'PRTSEN YARACUY (ACTUALIZADO)'!W1:W73,"0",0) -> #NAME? | F18: =_xlfn.XLOOKUP($A$2,'PRTSEN YARACUY (ACTUALIZADO)'!$AD$1:$AD$73,'PRTSEN YARACUY (ACTUALIZADO)'!X1:X73,"0",0) -> #NAME? | G18: =_xlfn.XLOOKUP($A$2,'PRTSEN YARACUY (ACTUALIZADO)'!$AD$1:$AD$73,'PRTSEN YARACUY (ACTUALIZADO)'!Y1:Y73,"0",0) -> #NAME? | H18: =_xlfn.XLOOKUP($A$2,'PRTSEN YARACUY (ACTUALIZADO)'!$AD$1:$AD$73,'PRTSEN YARACUY (ACTUALIZADO)'!Z1:Z73,"0",0) -> #NAME? | I18: =_xlfn.XLOOKUP($A$2,'PRTSEN YARACUY (ACTUALIZADO)'!$AD$1:$AD$73,'PRTSEN YARACUY (ACTUALIZADO)'!AA1:AA73,"0",0) -> #NAME? | J18: =_xlfn.XLOOKUP($A$2,'PRTSEN YARACUY (ACTUALIZADO)'!$AD$1:$AD$73,'PRTSEN YARACUY (ACTUALIZADO)'!AB1:AB73,"0",0) -> #NAME? | K18: =_xlfn.XLOOKUP($A$2,'PRTSEN YARACUY (ACTUALIZADO)'!$AD$1:$AD$73,'PRTSEN YARACUY (ACTUALIZADO)'!AC1:AC73,"0",0) -> #NAME?
A19: OBSERVACIONES
A20: =IF(_xlfn.XLOOKUP(A2,'PRTSEN YARACUY (ACTUALIZADO)'!AD1:AD73,'PRTSEN YARACUY (ACTUALIZADO)'!AF1:AF73,"",0)=0,"",_xlfn.XLOOKUP(A2,'PRTSEN YARACUY (ACTUALIZADO)'!AD1:AD73,'PRTSEN YARACUY (ACTUALIZADO)'!AF1:AF73,"",0)) -> #NAME?

Sheet SEGMENTO RECUPERAC
A4: YARACUY | D4: 2 | E4: 3 | J4: 6 | K4: 7 | M4: 8 | N4: 9 | P4: 10 | Q4: 11
A13: Responsable : | B13: GERENCIA GENERAL DE DISTRIBUCION | D13: SUBESTACIONES | G13: CIRCUITOS AEREOS Y SUBTERRANEOS | J13: TRANSFORMADORES DE POTENCIA | M13: COMPENSACIÓN REACTIVA EN LA RED | P13: PROTECCIONES SUPERVISIÓN, CONTROL Y MEDICIÓN REMOTA | S13: INVERSIONES
A14: Fecha :
A16: ENTIDAD FEDERAL | B16: =+A4 -> YARACUY | D16: CANTIDAD | E16: INVERSIÓN | G16: CANTIDAD | H16: INVERSIÓN | J16: CANTIDAD | K16: INVERSIÓN | M16: CANTIDAD | N16: INVERSIÓN | P16: CANTIDAD | Q16: INVERSIÓN | S16: INVERSIONES
D17: (No SE) | E17: (MM$) | G17: (No CIRCUITO) | H17: (MM$) | J17: (No TRX) | K17: (MM$) | M17: (No PROYECTO) | N17: (MM$) | P17: (No SE ) | Q17: (MM$) | S17: (MM$)
A19: RESTRICCIONES OPERATIVAS DE DISTRIBUCIÓN CED | D19: 1 | E19: 0.425 | G19: 69 | H19: 10.813499 | J19: 0 | K19: 0 | M19: 0 | N19: 0 | P19: 2 | Q19: 0.6837 | S19: =E19+H19+K19+N19+Q19 -> 11.922199
A25: PROBLEMÁTICA EN DISTRIBUCIÓN A NIVEL NACIONAL | D25: 0 | E25: 0 | G25: 3 | H25: 0.72676 | J25: 0 | K25: 0 | M25: 1 | N25: 0.35027387 | P25: 0 | Q25: 0 | S25: =E25+H25+K25+N25+Q25 -> 1.0770339
A31: EQUIPOS TRANSFORMADORES DE DE DISTRIBUCIÓN | D31: TRANSFORMADORES DE DISTRIBUCION DE 15, 25, 37.5, 50, 75, 100 KVA PARA LA ATENCION DEL 1X10 A RAZON DE 89 TRANSFORMADORES POR AÑOS | S31: 1.1125
A37: EQUIPOS (INTERRUPTORES SECCIONADORES) | D37: BANCO DE BATERIAS, INTERRUPTORES, RECONECTADORES, REGULADORES, SECCIONADORES, SERVICIOS AUXILIARES, SISTEMA DE PUESTA A TIERRA | S37: 0.162611
A43: MATERIALES DE ALTA ROTACIÓN | D43: AISLADORES POLIMÉRICOS Y DE PORCELANAS, TEIPES DE GOMA Y PLÁSTICO, PORTAFUSIBLES CON FUSIBLES, CONECTORES BIMETÁLICOS, COPAS TERMINALES, CONECTORES KS, CONECTORES TIPO AMPAC DE DIFERENTES CALIBRES, PLETINAS Y CRUCETAS, ABRAZADERAS, GRILLETES, PALILLOS, CABLES Y CONDUCTORES, CONEXIONES PREMOLDEADAS Y ACCESORIOS, CORTACORRIENTE Y/O SECCIONADOR, DESCARGADOR, POSTES. | S43: 2.9882372
N49: CANTIDAD DE PROYECTOS | S49: =+D19+D25+G19+G25+J19+J25+M19+M25+P19+P25 -> 76
N51: TOTAL (MM$) | S51: =+S43+S31+S25+S19+S37 -> 17.262581

Sheet PRT-YARACUY-1
A1: PRT-ESTADO-NNN
A2: PRT-YARACUY-1
A3: ESTADO | B3: MUNICIPIO | C3: DIRECCION | E3: SITUACION ACTUAL DEL PROYECTO | F3: FASE DEL PROYECTO | G3: TIPO DE INSTALACIÓN | H3: NOMBRE DE LA INSTALACIÓN | I3: NIVEL DE TENSIÓN | J3: UNIDAD DE MEDIDA ( MVA, MW, km) | K3: CAPACIDAD KM o MVAR
